Workbook

Sheet Master
A1: Type | B1: Sous-ensemble | C1: Sous-ensemble | D1: Sous-ensemble | E1: Sous-ensemble | F1: Sous-ensemble | G1: Sous-ensemble | H1: Sous-ensemble | I1: Sous-ensemble | J1: Sous-ensemble | K1: Sous-ensemble | L1: IFE | M1: IFE | N1: IFE | O1: Sous-ensemble | P1: Sous-ensemble | Q1: Sous-ensemble | R1: Sous-ensemble | S1: Sous-ensemble | T1: Sous-ensemble | U1: IFE | V1: IFE | W1: IFE | X1: Sous-ensemble | Y1: Sous-ensemble | Z1: Sous-ensemble | AA1: Sous-ensemble | AB1: Sous-ensemble | AC1: Sous-ensemble | AD1: Sous-ensemble | AE1: Sous-ensemble | AF1: Sous-ensemble | AG1: IFE | AH1: IFE | AI1: IFE | AJ1: Site assemblage | AK1: Site assemblage | AL1: Site assemblage | AM1: Site assemblage | AN1: Site assemblage | AO1: Sous-ensemble | AP1: Sous-ensemble | AQ1: Sous-ensemble | AR1: Sous-ensemble | AS1: Sous-ensemble | AT1: Sous-ensemble | AU1: Sous-ensemble | AV1: Sous-ensemble | AW1: Sous-ensemble | AX1: Sous-ensemble | AY1: Sous-ensemble | AZ1: Sous-ensemble | BA1: Sous-ensemble | BB1: Sous-ensemble | BC1: Sous-ensemble | BD1: Sous-ensemble | BE1: Sous-ensemble | BF1: Sous-ensemble | BG1: Sous-ensemble | BH1: Sous-ensemble | BI1: Sous-ensemble | BJ1: Sous-ensemble | BK1: Sous-ensemble | BL1: Sous-ensemble | BM1: Sous-ensemble | BN1: Sous-ensemble | BO1: Sous-ensemble | BP1: Sous-ensemble | BQ1: Sous-ensemble | BR1: Sous-ensemble | BS1: Sous-ensemble | BT1: Sous-ensemble | BU1: Sous-ensemble | BV1: Sous-ensemble | BW1: Sous-ensemble | BX1: Sous-ensemble | BY1: Sous-ensemble | BZ1: Sous-ensemble | CA1: Sous-ensemble | CB1: Sous-ensemble | CC1: Sous-ensemble | CD1: Sous-ensemble | CE1: Sous-ensemble | CF1: Sous-ensemble | CG1: Sous-ensemble | CH1: Sous-ensemble | CI1: Sous-ensemble | CJ1: Sous-ensemble | CK1: Sous-ensemble | CL1: Sous-ensemble | CM1: Sous-ensemble | CN1: Sous-ensemble | CO1: Sous-ensemble | CP1: Sous-ensemble | CQ1: Sous-ensemble | CR1: Sous-ensemble | CS1: Sous-ensemble | CT1: Sous-ensemble | CU1: Sous-ensemble | CV1: Sous-ensemble | CW1: Sous-ensemble | CX1: Sous-ensemble | CY1: Sous-ensemble | CZ1: Sous-ensemble | DA1: Sous-ensemble | DB1: Sous-ensemble | DC1: Sous-ensemble | DD1: Sous-ensemble | DE1: Sous-ensemble | DF1: Sous-ensemble | DG1: Sous-ensemble | DH1: Sous-ensemble | DI1: Sous-ensemble | DJ1: Sous-ensemble | DK1: Sous-ensemble | DL1: Sous-ensemble | DM1: Sous-ensemble | DN1: Sous-ensemble | DO1: Sous-ensemble | DP1: Sous-ensemble | DQ1: Sous-ensemble | DR1: Sous-ensemble | DS1: Sous-ensemble | DT1: Sous-ensemble | DU1: Sous-ensemble | DV1: Sous-ensemble | DW1: Sous-ensemble | DX1: Sous-ensemble | DY1: Sous-ensemble | DZ1: Sous-ensemble | EA1: Sous-ensemble | EB1: Sous-ensemble | EC1: Sous-ensemble | ED1: Sous-ensemble | EE1: Sous-ensemble | EF1: Sous-ensemble | EG1: Sous-ensemble | EH1: Sous-ensemble | EI1: Sous-ensemble | EJ1: Sous-ensemble | EK1: Sous-ensemble | EL1: Sous-ensemble | EM1: Sous-ensemble | EN1: Sous-ensemble | EO1: Sous-ensemble | EP1: Sous-ensemble | EQ1: Sous-ensemble | ER1: Sous-ensemble | ES1: Sous-ensemble | ET1: Sous-ensemble | EU1: Sous-ensemble | EV1: Sous-ensemble | EW1: Sous-ensemble | EX1: Sous-ensemble | EY1: Sous-ensemble | EZ1: Sous-ensemble | FA1: Sous-ensemble | FB1: Sous-ensemble | FC1: Sous-ensemble | FD1: Sous-ensemble | FE1: Sous-ensemble | FF1: Sous-ensemble | FG1: Sous-ensemble | FH1: Sous-ensemble | FI1: Sous-ensemble | FJ1: Sous-ensemble | FK1: Sous-ensemble | FL1: Sous-ensemble | FM1: Sous-ensemble | FN1: Sous-ensemble | FO1: Sous-ensemble | FP1: Sous-ensemble | FQ1: Sous-ensemble | FR1: Sous-ensemble | FS1: Sous-ensemble | FT1: Sous-ensemble | FU1: Sous-ensemble | FV1: Sous-ensemble | FW1: Sous-ensemble | FX1: Sous-ensemble | FY1: Sous-ensemble | FZ1: Sous-ensemble | GA1: Sous-ensemble | GB1: Sous-ensemble | GC1: Sous-ensemble | GD1: Sous-ensemble | GE1: Sous-ensemble | GF1: Sous-ensemble | GG1: Sous-ensemble | GH1: Sous-ensemble | GI1: Sous-ensemble | GJ1: Sous-ensemble | GK1: Sous-ensemble | GL1: Sous-ensemble | GM1: Sous-ensemble | GN1: Sous-ensemble | GO1: Sous-ensemble | GP1: Sous-ensemble | GQ1: Sous-ensemble | GR1: Sous-ensemble | GS1: Sous-ensemble | GT1: Sous-ensemble | GU1: Sous-ensemble | GV1: Sous-ensemble | GW1: Sous-ensemble | GX1: Sous-ensemble | GY1: Sous-ensemble | GZ1: Sous-ensemble | HA1: Sous-ensemble | HB1: Sous-ensemble | HC1: Sous-ensemble | HD1: Sous-ensemble | HE1: Sous-ensemble | HF1: Sous-ensemble | HG1: Sous-ensemble | HH1: Sous-ensemble | HI1: Sous-ensemble | HJ1: Sous-ensemble | HK1: Sous-ensemble | HL1: Sous-ensemble | HM1: Sous-ensemble | HN1: Sous-ensemble | HO1: Sous-ensemble | HP1: Sous-ensemble | HQ1: Sous-ensemble | HR1: Sous-ensemble | HS1: Sous-ensemble | HT1: Sous-ensemble | HU1: Sous-ensemble | HV1: Sous-ensemble | HW1: Sous-ensemble | HX1: Sous-ensemble | HY1: Livraison | HZ1: Livraison | IA1: Utilisation 1 an | IB1: Utilisation 1 an | IC1: Utilisation 1 an | ID1: Utilisation 7 ans | IE1: Utilisation 7 ans | IF1: Utilisation 7 ans | IG1: Fin de vie | IH1: Fin de vie | II1: Fin de vie | IJ1: Fin de vie | IK1: Fin de vie | IL1: Fin de vie | IM1: Fin de vie | IN1: Fin de vie | IO1: Fin de vie | IP1: Fin de vie | IQ1: Fin de vie | IR1: Fin de vie | IS1: Fin de vie | IT1: Fin de vie | IU1: Fin de vie | IV1: Fin de vie | IW1: Fin de vie | IX1: Fin de vie | IY1: Fin de vie | IZ1: Fin de vie
A2: Système | B2: Brackets set | C2: Brackets set | D2: Brackets set | E2: Ceinture de sécurité | F2: Ceinture de sécurité | G2: Ceinture de sécurité | H2: Ceinture de sécurité | I2: Commande actionnement ECU | J2: Commande actionnement ECU | K2: Commande actionnement ECU | L2: Ecran | M2: Ecran | N2: Ecran | O2: lightning | P2: lightning | Q2: lightning | R2: Padding | S2: Padding | T2: Padding | U2: Powerbox | V2: Powerbox | W2: Powerbox | X2: Remote extender unit | Y2: Remote extender unit | Z2: Remote extender unit | AA2: SFCU | AB2: SFCU | AC2: SFCU | AD2: Support clamps | AE2: Support clamps | AF2: Support clamps | AG2: System IFE | AH2: System IFE | AI2: System IFE | AJ2: Site assemblage | AK2: Site assemblage | AL2: Site assemblage | AM2: Site assemblage | AN2: Site assemblage | AO2: Accoudoir allée | AP2: Accoudoir allée | AQ2: Accoudoir allée | AR2: Accoudoir allée | AS2: Accoudoir allée | AT2: Accoudoir allée | AU2: Accoudoir allée | AV2: Accoudoir allée | AW2: Accoudoir allée | AX2: Accoudoir allée | AY2: Bumper version porte | AZ2: Bumper version porte | BA2: Bumper version porte | BB2: Bumper version porte | BC2: Bumper version porte | BD2: Bumper version porte | BE2: Capot NFC | BF2: Capot NFC | BG2: Capot NFC | BH2: Coussin ottoman | BI2: Coussin ottoman | BJ2: Coussin ottoman | BK2: Coussin ottoman | BL2: Coussin ottoman | BM2: Coussin ottoman | BN2: Coussin têtière | BO2: Coussin têtière | BP2: Coussin têtière | BQ2: Coussin têtière | BR2: Coussin têtière | BS2: Coussin têtière | BT2: Ens. Coussin assise | BU2: Ens. Coussin assise | BV2: Ens. Coussin assise | BW2: Ens. Coussin assise | BX2: Ens. Coussin assise | BY2: Ens.coussin dossier version têtière | BZ2: Ens.coussin dossier version têtière | CA2: Ens.coussin dossier version têtière | CB2: Ens.coussin dossier version têtière | CC2: Ens.coussin dossier version têtière | CD2: Ens.coussin dossier version têtière | CE2: Ens. Coussin dossier | CF2: Ens. Coussin dossier | CG2: Ens. Coussin dossier | CH2: Ens. Coussin dossier | CI2: Ens. Coussin dossier | CJ2: Ens. Coussin dossier | CK2: Ens. Stowage latéral | CL2: Ens. Stowage latéral | CM2: Ens. Stowage latéral | CN2: Ens. Stowage latéral | CO2: Ens. Stowage latéral | CP2: Ens. Stowage latéral | CQ2: Ens. Stowage latéral | CR2: Ens. Stowage latéral | CS2: Ens. Stowage latéral | CT2: Ens. Stowage latéral | CU2: Ens. Stowage latéral | CV2: Ens. Coque | CW2: Ens. Coque | CX2: Ens. Coque | CY2: Ens. Coque | CZ2: Ens. Coque | DA2: Ens. Equipements latéraux | DB2: Ens. Equipements latéraux | DC2: Ens. Equipements latéraux | DD2: Ens. Equipements latéraux | DE2: Ens. Equipements latéraux | DF2: Ens. Equipements latéraux | DG2: Ens. Equipements latéraux | DH2: Ens. Palette optimisée | DI2: Ens. Palette optimisée | DJ2: Ens. Palette optimisée | DK2: Ens. Palette optimisée | DL2: Ens. Palette optimisée | DM2: Ens. Palette optimisée | DN2: Ens. Palette optimisée | DO2: Ens. Palette optimisée | DP2: Ens. Palette optimisée | DQ2: Ensemble porte | DR2: Ensemble porte | DS2: Ensemble porte | DT2: Ensemble porte | DU2: Ensemble porte | DV2: Ensemble porte | DW2: Ensemble porte | DX2: Ensemble porte | DY2: Ensemble porte | DZ2: Ens. Structure fauteuil | EA2: Ens. Structure fauteuil | EB2: Ens. Structure fauteuil | EC2: Ens. Structure fauteuil | ED2: Ens. Structure fauteuil | EE2: Ens. Structure fauteuil | EF2: Ens. Structure fauteuil | EG2: Ens. Structure fauteuil | EH2: Ens. Structure fauteuil | EI2: Ens. Structure fauteuil | EJ2: Ens. Structure porte | EK2: Ens. Structure porte | EL2: Ens. Structure fixe | EM2: Ens. Structure fixe | EN2: Ens. Structure fixe | EO2: Ens. Structure fixe | EP2: Ens. Structure fixe | EQ2: Ens. Structure fixe | ER2: Ens. Structure fixe | ES2: Ens. Structure fixe | ET2: Ens. Tablette cocktail | EU2: Ens. Tablette cocktail | EV2: Ens. Tablette cocktail | EW2: Ens. Tablette cocktail | EX2: Ens. Tablette cocktail | EY2: Ens. Tablette cocktail | EZ2: Ens. Tablette cocktail | FA2: Ens. Tablette cocktail | FB2: Ens. Tablette cocktail | FC2: Ens. Tablette repas | FD2: Ens. Tablette repas | FE2: Ens. Tablette repas | FF2: Ens. Tablette repas | FG2: Ens. Tablette repas | FH2: Ens. Tablette repas | FI2: Ens. Tablette repas | FJ2: Ens. Tablette repas | FK2: Ens. Tablette repas | FL2: Ens. Tablette repas | FM2: Ens. Tablette repas | FN2: Ens. Têtière | FO2: Ens. Têtière | FP2: Ens. Têtière | FQ2: Ens. Têtière | FR2: Ens. Têtière | FS2: Ens. Têtière | FT2: Ens. Têtière | FU2: Habillage sous fauteuil | FV2: Habillage sous fauteuil | FW2: Habillage sous fauteuil | FX2: Habillage sous fauteuil | FY2: Habillage sous fauteuil | FZ2: Manchette acc. Mobile | GA2: Manchette acc. Mobile | GB2: Manchette acc. Mobile | GC2: Manchette acc. Mobile | GD2: Manchette acc. Mobile | GE2: Manchette acc. Mobile | GF2: Manchette équipée | GG2: Manchette équipée | GH2: Manchette équipée | GI2: Manchette équipée | GJ2: Manchette équipée | GK2: Manchette équipée | GL2: Manchette équipée | GM2: Renfort tubulaire | GN2: Renfort tubulaire | GO2: Renfort tubulaire | GP2: Renfort tubulaire | GQ2: Renfort tubulaire | GR2: Stowage assemblé avec porte | GS2: Stowage assemblé avec porte | GT2: Stowage assemblé avec porte | GU2: Stowage assemblé avec porte | GV2: Stowage assemblé avec porte | GW2: Stowage assemblé avec porte | GX2: Stowage assemblé avec porte | GY2: Stowage assemblé avec porte | GZ2: Stowage assemblé avec porte | HA2: Stowage assemblé avec porte | HB2: Stowage assemblé avec porte | HC2: Structure ottoman horizontale | HD2: Structure ottoman horizontale | HE2: Structure ottoman horizontale | HF2: Structure ottoman horizontale | HG2: Structure ottoman horizontale | HH2: Support écran | HI2: Support écran | HJ2: Support écran | HK2: Support écran | HL2: Support écran | HM2: Support écran | HN2: Support équipé | HO2: Support équipé | HP2: Support équipé | HQ2: Support équipé | HR2: Support manchette équipée | HS2: Support manchette équipée | HT2: Support manchette équipée | HU2: Support manchette équipée | HV2: Support NFC | HW2: Support NFC | HX2: Support NFC | HY2: Livraison à Hambourg | HZ2: Livraison à Hambourg | IA2: Consommation passive | IB2: Consommation passive | IC2: Entretien | ID2: Consommation passive | IE2: Consommation passive | IF2: Entretien | IG2: Enfouissement | IH2: Enfouissement | II2: Enfouissement | IJ2: Enfouissement | IK2: Enfouissement | IL2: Recyclage | IM2: Recyclage | IN2: Recyclage | IO2: Recyclage | IP2: Recyclage | IQ2: Recyclage | IR2: Recyclage | IS2: Recyclage | IT2: Recyclage | IU2: Recyclage | IV2: Recyclage | IW2: Recyclage | IX2: Recyclage | IY2: Recyclage | IZ2: Recyclage
A3: Composant | B3: cables | C3: packaging | D3: Transport | E3: acier | F3: nylon | G3: packaging | H3: Transport | I3: Commande actionnement ECU | J3: packaging | K3: Transport | L3: Ecran | M3: packaging | N3: Transport | O3: lightning | P3: packaging | Q3: Transport | R3: packaging | S3: Padding | T3: Transport | U3: packaging | V3: powerbox | W3: Transport | X3: packaging | Y3: télécommande | Z3: Transport | AA3: packaging | AB3: Clavier | AC3: Transport | AD3: acier | AE3: nylon | AF3: packaging | AG3: packaging | AH3: System IFE boitier | AI3: Transport | AJ3: élec atelier | AK3: élec bureaux | AL3: gaz atelier | AM3: gaz bureaux | AN3: papierassemblage | AO3: 30NCD6 | AP3: A2017 | AQ3: A2024 | AR3: A5086 | AS3: acier | AT3: Alu | AU3: Ertalon | AV3: inox | AW3: packaging | AX3: Transport | AY3: A5086 | AZ3: acier | BA3: alliage Cu | BB3: Copolymere Lexan FST | BC3: packaging | BD3: Transport | BE3: kydex | BF3: packaging | BG3: Transport | BH3: FRMC55 | BI3: kydex | BJ3: packaging | BK3: tissu | BL3: Transport | BM3: velours | BN3: FRMC55 | BO3: packaging | BP3: tissu | BQ3: Transport | BR3: velcro | BS3: velours | BT3: FRMC55 | BU3: packaging | BV3: tissu | BW3: Transport | BX3: velours | BY3: FRMC55 | BZ3: packaging | CA3: tissu | CB3: Transport | CC3: velcro | CD3: velours | CE3: FRMC55 | CF3: packaging | CG3: tissu | CH3: Transport | CI3: velcro | CJ3: velours | CK3: 15CDV6 | CL3: A2017 | CM3: A5086 | CN3: acier | CO3: cuir | CP3: Ertalon | CQ3: FRMC55 | CR3: kydex | CS3: nylon | CT3: packaging | CU3: Transport | CV3: acier | CW3: NIDA | CX3: packaging | CY3: Résine BR623 | CZ3: Transport | DA3: A5086 | DB3: acier | DC3: Ertalon | DD3: nylon | DE3: packaging | DF3: Transport | DG3: velours | DH3: 35NC6 | DI3: A2017 | DJ3: acier | DK3: Alu | DL3: inox | DM3: nylon | DN3: packaging | DO3: Polychloroprene | DP3: Transport | DQ3: acier | DR3: AER film | DS3: Alu | DT3: Ertalon | DU3: inox | DV3: kydex | DW3: nylon | DX3: packaging | DY3: Transport | DZ3: 35NC6 | EA3: 4140 | EB3: A2017 | EC3: A2024 | ED3: A5086 | EE3: acier | EF3: inox | EG3: nylon | EH3: packaging | EI3: Transport | EJ3: velcro | EK3: Z10CNT18 | EL3: 35NC6 | EM3: acier | EN3: Alu | EO3: caoutchouc | EP3: inox | EQ3: nylon | ER3: packaging | ES3: Transport | ET3: A2017 | EU3: A2024 | EV3: acier | EW3: inox | EX3: kydex | EY3: nylon | EZ3: packaging | FA3: tissu | FB3: Transport | FC3: A2017 | FD3: A2024 | FE3: A2075 | FF3: acier | FG3: Ertalon | FH3: inox | FI3: kydex | FJ3: nylon | FK3: packaging | FL3: Silicone50 shore | FM3: Transport | FN3: A2017 | FO3: A2024 | FP3: inox | FQ3: nylon | FR3: packaging | FS3: tissu | FT3: Transport | FU3: A5086 | FV3: acier | FW3: packaging | FX3: Transport | FY3: velours | FZ3: A5086 | GA3: Alu | GB3: cuir | GC3: FRMC55 | GD3: packaging | GE3: Transport | GF3: A5086 | GG3: acier | GH3: cuir | GI3: FRMC55 | GJ3: packaging | GK3: Transport | GL3: velcro | GM3: A5086 | GN3: A6060 | GO3: acier | GP3: packaging | GQ3: Transport | GR3: 35NC6 | GS3: A2017 | GT3: A5086 | GU3: acier | GV3: Ertalon | GW3: inox | GX3: kydex | GY3: nylon | GZ3: packaging | HA3: Silicone | HB3: Transport | HC3: A5086 | HD3: acier | HE3: Ertalon | HF3: packaging | HG3: Transport | HH3: A2017 | HI3: A5086 | HJ3: acier | HK3: inox | HL3: packaging | HM3: Transport | HN3: A5086 | HO3: acier | HP3: packaging | HQ3: Transport | HR3: A5086 | HS3: acier | HT3: packaging | HU3: Transport | HV3: A5086 | HW3: packaging | HX3: Transport | HY3: packaging | HZ3: Transport | IA3: EU-28: Kerosene / Jet A1 at refinery Sphera | IB3: GLO: Cargo plane, 65 t payload Sphera <u-so> | IC3: Nettoyage et désinfection | ID3: EU-28: Kerosene / Jet A1 at refinery Sphera | IE3: GLO: Cargo plane, 65 t payload Sphera <u-so> | IF3: Nettoyage et désinfection | IG3: Landfill Acier (11,54 kg) | IH3: Landfill Aluminium (69,53 kg) | II3: Landfill DEEE (9,55 kg) | IJ3: landfill plastique (21,36 kg) | IK3: landfill textile (2,34 kg) | IL3: Credit Recyclage Acier | IM3: Credit Recyclage Aluminium | IN3: Credit Recyclage DEEE | IO3: Credit Recyclage plastiques | IP3: incinération Covers | IQ3: Incineration plastiques | IR3: Mise en décharche Acier | IS3: Mise en décharge Aluminium | IT3: Mise en décharge DEEE | IU3: Mise en décharge Plastiques | IV3: Mise en décharge Textile | IW3: Process recyclage Acier | IX3: Process recyclage Alu | IY3: Process recyclage DEEE | IZ3: Process recyclage Plastiques
A4: EF 3.0 Acidification [Mole of H+ eq.] | B4: 0.0522 | C4: 0.00103 | D4: 0.000316 | E4: 0.00568 | F4: 0.00299 | G4: 0.000968 | H4: 0.0215 | I4: 2.13 | J4: 0.00486 | K4: 0.000324 | L4: 1.33 | M4: 0.00729 | N4: 0.0865 | O4: 1.25 | P4: 0.00486 | Q4: 0.000333 | R4: 0.00426 | S4: 0.0286 | T4: 0.00159 | U4: 0.00486 | V4: 0.169 | W4: 0.0558 | X4: 0.00486 | Y4: 0.315 | Z4: 0.000198 | AA4: 0.00486 | AB4: 0.0349 | AC4: 0.0158 | AD4: 0.0101 | AE4: 0.0219 | AF4: 1.94e-06 | AG4: 0.00486 | AH4: 1.25 | AI4: 0.000324 | AJ4: 0.0247 | AK4: 0.00131 | AL4: 0.00921 | AM4: 0.000695 | AN4: 1.15e-05 | AO4: 0.00021161998 | AP4: 0.132 | AQ4: 0.00802 | AR4: 0.0141 | AS4: 0.00556 | AT4: 0.00525 | AU4: 0.000162 | AV4: 0.000516 | AW4: 0.000109 | AX4: 0.00202 | AY4: 0.00108 | AZ4: 0.000188 | BA4: 9.23e-05 | BB4: 0.00113 | BC4: 0.000679 | BD4: 0.0013 | BE4: 0.000433 | BF4: 0.000509 | BG4: 2.42e-05 | BH4: 0.00923 | BI4: 0.000232 | BJ4: 0.00326 | BK4: 0.176 | BL4: 0.00248 | BM4: 0.000438 | BN4: 0.00111 | BO4: 0.000679 | BP4: 0.105 | BQ4: 0.000447 | BR4: 9.02e-05 | BS4: 3.87e-05 | BT4: 0.008 | BU4: 0.00295 | BV4: 0.228 | BW4: 0.00188 | BX4: 0.000322 | BY4: 0.00784 | BZ4: 0.00326 | CA4: 0.425 | CB4: 0.00224 | CC4: 6.44e-05 | CD4: 0.000103 | CE4: 0.01 | CF4: 0.00326 | CG4: 0.413 | CH4: 0.00246 | CI4: 7.73e-05 | CJ4: 0.000283 | CK4: 0.000172 | CL4: 0.00622 | CM4: 0.00967 | CN4: 0.000119 | CO4: 0.00256 | CP4: 4.8221809e-05 | CQ4: 0.000147 | CR4: 0.00728 | CS4: 0.000102 | CT4: 9.72e-05 | CU4: 0.000764 | CV4: 0.00188 | CW4: 0.0571 | CX4: 0.022 | CY4: 0.013 | CZ4: 0.00452 | DA4: 0.163 | DB4: 0.000781 | DC4: 2.8e-06 | DD4: 4.39e-05 | DE4: 2.36e-08 | DF4: 0.00495 | DG4: 0.000103 | DH4: 0.000447 | DI4: 0.713 | DJ4: 0.00455 | DK4: 0.00961 | DL4: 0.000677 | DM4: 0.000681 | DN4: 0.000511 | DO4: 2.32e-05 | DP4: 0.00821 | DQ4: 0.000338 | DR4: 0.00246 | DS4: 0.314 | DT4: 3.21e-05 | DU4: 0.000136 | DV4: 0.00868 | DW4: 0.000177 | DX4: 0.000511 | DY4: 0.00401 | DZ4: 0.0123 | EA4: 1.74e-05 | EB4: 0.78 | EC4: 0.318 | ED4: 0.0213 | EE4: 0.0146 | EF4: 0.00133 | EG4: 0.00247 | EH4: 0.0106 | EI4: 0.632 | EJ4: 0.000773 | EK4: 0.0256 | EL4: 0.00011 | EM4: 0.0112 | EN4: 0.188 | EO4: 0.000169 | EP4: 0.00077 | EQ4: 0.000454 | ER4: 0.00397 | ES4: 0.00154 | ET4: 0.756 | EU4: 0.0146 | EV4: 0.00888 | EW4: 0.000342 | EX4: 0.00285 | EY4: 0.00444 | EZ4: 7.84e-05 | FA4: 0.00116 | FB4: 0.0013 | FC4: 0.26664123 | FD4: 0.076474855 | FE4: 0.0014689978 | FF4: 0.00091310102 | FG4: 0.00011321428 | FH4: 0.000399 | FI4: 0.00037 | FJ4: 0.000604 | FK4: 4.67e-05 | FL4: 1.34e-05 | FM4: 0.000992 | FN4: 0.0197 | FO4: 0.00129 | FP4: 2.68e-05 | FQ4: 5.92e-05 | FR4: 0.00155 | FS4: 0.105 | FT4: 0.000207 | FU4: 0.0513 | FV4: 0.000212 | FW4: 2.36e-08 | FX4: 0.000329 | FY4: 9.02e-05 | FZ4: 0.00488 | GA4: 4.55e-05 | GB4: 0.000891 | GC4: 0.000358 | GD4: 1.68e-05 | GE4: 0.0152 | GF4: 0.00789 | GG4: 0.000162 | GH4: 0.00137 | GI4: 0.000358 | GJ4: 1.68e-05 | GK4: 0.0172 | GL4: 7.73e-05 | GM4: 0.0417 | GN4: 0.0138 | GO4: 0.00045 | GP4: 0.00225 | GQ4: 0.000883 | GR4: 6.2702216e-05 | GS4: 0.30200223 | GT4: 0.11008127 | GU4: 0.00073955775 | GV4: 0.00032147873 | GW4: 0.000265 | GX4: 0.00142 | GY4: 0.000681 | GZ4: 8.76e-05 | HA4: 1.34e-05 | HB4: 0.00186 | HC4: 0.0863 | HD4: 0.000522 | HE4: 4.41e-06 | HF4: 7.3e-05 | HG4: 0.000352 | HH4: 0.1 | HI4: 0.0227 | HJ4: 0.00045 | HK4: 0.000399 | HL4: 4.38e-05 | HM4: 0.000666 | HN4: 0.00443 | HO4: 2.35e-05 | HP4: 0.000509 | HQ4: 2.83e-05 | HR4: 0.00524 | HS4: 4.58e-05 | HT4: 0.000509 | HU4: 3.09e-05 | HV4: 0.000448 | HW4: 0.000509 | HX4: 1.68e-05 | HY4: 0.0807 | HZ4: 0.117 | IA4: 28.1 | IB4: 235 | IC4: 0.0652 | ID4: =IA4*7 -> 196.7 | IE4: =IB4*7 -> 1645 | IF4: =IC4*7 -> 0.4564 | IG4: 0.00124 | IH4: 0.00749 | II4: 0.0162 | IJ4: 0.00459 | IK4: 0.000854 | IL4: -0.258 | IM4: -2.62 | IN4: -2.29 | IO4: -0.0502 | IP4: 0.000835 | IQ4: -0.010884866 | IR4: 0.00018634277 | IS4: 0.0011235354 | IT4: 0.011641631 | IU4: 0.0011828875 | IV4: 0.00076455769 | IW4: 0.0082 | IX4: 0.0494 | IY4: 0.00708 | IZ4: 0.00122
A5: EF 3.0 Climate Change - total [kg CO2 eq.] | B5: 19.1 | C5: 0.263 | D5: 0.0529 | E5: 2.16 | F5: 1.69 | G5: 0.244 | H5: 5.37 | I5: 291 | J5: 0.928 | K5: 0.0542 | L5: 174 | M5: 1.39 | N5: 21.6 | O5: 215 | P5: 0.928 | Q5: 0.0558 | R5: 0.738 | S5: 3.98 | T5: 0.265 | U5: 0.928 | V5: 21.8 | W5: 13.9 | X5: 0.928 | Y5: 43.7 | Z5: 0.0332 | AA5: 0.928 | AB5: 5.48 | AC5: 3.95 | AD5: 3.81 | AE5: 9.12 | AF5: 0.000371 | AG5: 0.928 | AH5: 582 | AI5: 0.0542 | AJ5: 10.5 | AK5: 0.56 | AL5: 13.7 | AM5: 1.03 | AN5: 0.00144 | AO5: 0.080054962 | AP5: 28.7 | AQ5: 1.63 | AR5: 3.19 | AS5: 2.11 | AT5: 1.07 | AU5: 0.0732 | AV5: 0.079 | AW5: 0.0179 | AX5: 0.338 | AY5: 0.243 | AZ5: 0.0712 | BA5: 0.0114 | BB5: 0.591 | BC5: 0.117 | BD5: 0.218 | BE5: 0.164 | BF5: 0.0875 | BG5: 0.00404 | BH5: 3.69 | BI5: 0.0877 | BJ5: 0.56 | BK5: 7.14 | BL5: 0.416 | BM5: 0.222 | BN5: 0.444 | BO5: 0.117 | BP5: 4.23 | BQ5: 0.0748 | BR5: 0.0456 | BS5: 0.0196 | BT5: 3.2 | BU5: 0.508 | BV5: 9.24 | BW5: 0.315 | BX5: 0.163 | BY5: 3.13 | BZ5: 0.56 | CA5: 17.2 | CB5: 0.375 | CC5: 0.0326 | CD5: 0.0521 | CE5: 4 | CF5: 0.56 | CG5: 16.7 | CH5: 0.412 | CI5: 0.0391 | CJ5: 0.143 | CK5: 0.0652 | CL5: 1.4 | CM5: 2.18 | CN5: 0.0451 | CO5: 0.357 | CP5: 0.021820198 | CQ5: 0.0587 | CR5: 2.75 | CS5: 0.0426 | CT5: 0.0159 | CU5: 0.128 | CV5: 0.984 | CW5: 21.9 | CX5: 6.01 | CY5: 4.81 | CZ5: 0.756 | DA5: 36.8 | DB5: 0.295 | DC5: 0.00127 | DD5: 0.0183 | DE5: 3.86e-06 | DF5: 0.828 | DG5: 0.0521 | DH5: 0.169 | DI5: 159 | DJ5: 1.72 | DK5: 2.2 | DL5: 0.104 | DM5: 0.284 | DN5: 0.0837 | DO5: 0.0143 | DP5: 1.37 | DQ5: 0.128 | DR5: 0.929 | DS5: 64 | DT5: 0.0145 | DU5: 0.0208 | DV5: 3.28 | DW5: 0.0739 | DX5: 0.0837 | DY5: 0.671 | DZ5: 4.41 | EA5: 0.00622 | EB5: 161 | EC5: 65.4 | ED5: 4.68 | EE5: 5.25 | EF5: 0.199 | EG5: 0.653 | EH5: 1.85 | EI5: 158 | EJ5: 0.391 | EK5: 3.84 | EL5: 0.0575 | EM5: 4.25 | EN5: 40.7 | EO5: 0.0502 | EP5: 0.118 | EQ5: 0.189 | ER5: 1.12 | ES5: 0.258 | ET5: 162 | EU5: 3.49 | EV5: 3.36 | EW5: 0.0523 | EX5: 1.08 | EY5: 1.85 | EZ5: 0.021 | FA5: 0.0468 | FB5: 0.217 | FC5: 60.130936 | FD5: 16.028695 | FE5: 0.29786417 | FF5: 0.34542234 | FG5: 0.051234094 | FH5: 0.0611 | FI5: 0.14 | FJ5: 0.252 | FK5: 0.00765 | FL5: 0.0047 | FM5: 0.166 | FN5: 3.99 | FO5: 0.262 | FP5: 0.00377 | FQ5: 0.0247 | FR5: 0.259 | FS5: 4.23 | FT5: 0.0346 | FU5: 13.3 | FV5: 0.0803 | FW5: 3.86e-06 | FX5: 0.055 | FY5: 0.0456 | FZ5: 1.07 | GA5: 0.0091 | GB5: 0.124 | GC5: 0.143 | GD5: 0.00263 | GE5: 3.77 | GF5: 1.74 | GG5: 0.0571 | GH5: 0.191 | GI5: 0.143 | GJ5: 0.00263 | GK5: 4.28 | GL5: 0.0391 | GM5: 9.41 | GN5: 3.75 | GO5: 0.17 | GP5: 0.619 | GQ5: 0.148 | GR5: 0.023719989 | GS5: 73.118711 | GT5: 24.895417 | GU5: 0.27977163 | GV5: 0.14546799 | GW5: 0.0405 | GX5: 0.536 | GY5: 0.284 | GZ5: 0.0143 | HA5: 0.0047 | HB5: 0.312 | HC5: 19.5 | HD5: 0.198 | HE5: 0.00199 | HF5: 0.0119 | HG5: 0.0589 | HH5: 23.5 | HI5: 5.21 | HJ5: 0.17 | HK5: 0.0611 | HL5: 0.00717 | HM5: 0.111 | HN5: 1 | HO5: 0.00889 | HP5: 0.0875 | HQ5: 0.00473 | HR5: 1.18 | HS5: 0.017 | HT5: 0.0875 | HU5: 0.00517 | HV5: 0.101 | HW5: 0.0875 | HX5: 0.00281 | HY5: 19.4 | HZ5: 19.6 | IA5: 8260 | IB5: 57600 | IC5: 11.6 | ID5: =IA5*7 -> 57820 | IE5: 403200 | IF5: =IC5*7 -> 81.2 | IG5: 0.176 | IH5: 1.06 | II5: 3.08 | IJ5: 1.53 | IK5: 2.97 | IL5: -39.8 | IM5: -540 | IN5: -473 | IO5: -19.8 | IP5: -0.406 | IQ5: 9.9101112 | IR5: 0.026323092 | IS5: 0.15874452 | IT5: 2.2186025 | IU5: 0.39595327 | IV5: 2.6583038 | IW5: 3.34 | IX5: 20.1 | IY5: 2.92 | IZ5: 1
A6: EF 3.0 Climate Change, biogenic [kg CO2 eq.] | B6: 0.0672 | C6: 0.00903 | D6: 0.000158 | E6: 0.000841 | F6: 0.00437 | G6: 0.00923 | H6: 0.0066 | J6: 0.108 | K6: 0.000162 | M6: 0.163 | N6: 0.0266 | P6: 0.108 | Q6: 0.000167 | R6: 0.111 | T6: 0.000793 | U6: 0.108 | W6: 0.0171 | X6: 0.108 | Z6: 9.92e-05 | AA6: 0.108 | AC6: 0.00485 | AD6: 0.00155 | AE6: 0.00121 | AF6: 4.34e-05 | AG6: 0.108 | AI6: 0.000162 | AJ6: 0.0846 | AK6: 0.00449 | AL6: 0.0115 | AM6: 0.000871 | AO6: 3.2577121e-05 | AP6: 0.0356 | AQ6: 0.00216 | AR6: 0.00378 | AS6: 0.000857 | AT6: 0.0014 | AU6: 9.43e-06 | AV6: 6.67e-05 | AW6: 0.0155 | AX6: 0.00101 | AY6: 0.000289 | AZ6: 2.9e-05 | BA6: 9.77e-07 | BB6: 0.000623 | BC6: 0.0184 | BD6: 0.000651 | BE6: 0.00107 | BF6: 0.0138 | BG6: 1.21e-05 | BH6: 0.00118 | BI6: 0.000572 | BJ6: 0.0884 | BL6: 0.00124 | BM6: 0.000433 | BN6: 0.000142 | BO6: 0.0184 | BQ6: 0.000224 | BR6: 8.91e-05 | BS6: 3.82e-05 | BT6: 0.00103 | BU6: 0.0801 | BW6: 0.000942 | BX6: 0.000318 | BY6: 0.00101 | BZ6: 0.0884 | CB6: 0.00112 | CC6: 6.36e-05 | CD6: 0.000102 | CE6: 0.00128 | CF6: 0.0884 | CH6: 0.00123 | CI6: 7.63e-05 | CJ6: 0.00028 | CK6: 2.65e-05 | CL6: 0.00173 | CM6: 0.00258 | CN6: 1.83e-05 | CP6: 2.9411074e-06 | CQ6: 1.88e-05 | CR6: 0.0179 | CS6: 5.66e-06 | CT6: 0.0138 | CU6: 0.000382 | CV6: -0.000242 | CW6: 0.0386 | CX6: 4.53 | CY6: 0.000478 | CZ6: 0.00226 | DA6: 0.0438 | DB6: 0.00012 | DC6: 1.63e-07 | DD6: 2.43e-06 | DE6: 3.33e-06 | DF6: 0.00248 | DG6: 0.000102 | DH6: 6.88e-05 | DI6: 0.197 | DJ6: 0.0007 | DK6: 0.00256 | DL6: 8.74e-05 | DM6: 3.77e-05 | DN6: 0.0723 | DO6: 6.55e-05 | DP6: 0.00411 | DQ6: 5.2e-05 | DR6: 0.00606 | DS6: 0.0817 | DT6: 1.96e-06 | DU6: 1.75e-05 | DV6: 0.0214 | DW6: 9.8e-06 | DX6: 0.0723 | DY6: 0.00201 | DZ6: 0.00103 | EA6: 1.45e-06 | EB6: 0.194 | EC6: 0.0783 | ED6: 0.00546 | EE6: 0.00122 | EF6: 0.000165 | EG6: 5.01e-05 | EH6: 0.276 | EI6: 0.194 | EJ6: 0.000763 | EK6: 0.00317 | EL6: -1.41e-05 | EM6: 0.00173 | EN6: 0.0517 | EO6: 0.000393 | EP6: 9.94e-05 | EQ6: 2.51e-05 | ER6: 0.897 | ES6: 0.000771 | ET6: 0.208 | EU6: 0.00103 | EV6: 0.00137 | EW6: 4.42e-05 | EX6: 0.00702 | EY6: 0.000246 | EZ6: 0.0124 | FB6: 0.000649 | FC6: 0.075845752 | FD6: 0.020657869 | FE6: 0.00039249015 | FF6: 0.00014056424 | FG6: 6.5986647e-06 | FH6: 5.16e-05 | FI6: 0.000912 | FJ6: 3.35e-05 | FK6: 0.00661 | FL6: 3.23e-05 | FM6: 0.000496 | FN6: 0.00526 | FO6: 0.000345 | FP6: 3.01e-06 | FQ6: 3.43e-06 | FR6: 0.0483 | FT6: 0.000103 | FU6: 0.0216 | FV6: 3.27e-05 | FW6: 3.33e-06 | FX6: 0.000164 | FY6: 8.91e-05 | FZ6: 0.00125 | GA6: 1.19e-05 | GC6: 4.59e-05 | GD6: 0.00203 | GE6: 0.00473 | GF6: 0.00203 | GG6: 1.58e-05 | GI6: 4.59e-05 | GJ6: 0.00203 | GK6: 0.00535 | GL6: 7.63e-05 | GM6: 0.0111 | GN6: 0.00405 | GO6: 6.92e-05 | GP6: 0.452 | GQ6: 0.000442 | GR6: 9.6524803e-06 | GS6: 0.091441571 | GT6: 0.029595871 | GU6: 0.00011384871 | GV6: 1.9607382e-05 | GW6: 3.42e-05 | GX6: 0.00349 | GY6: 3.77e-05 | GZ6: 0.0124 | HA6: 3.23e-05 | HB6: 0.000932 | HC6: 0.0231 | HD6: 8.04e-05 | HE6: 2.57e-07 | HF6: 0.0103 | HG6: 0.000176 | HH6: 0.0276 | HI6: 0.00609 | HJ6: 6.92e-05 | HK6: 5.16e-05 | HL6: 0.0062 | HM6: 0.000333 | HN6: 0.00118 | HO6: 3.62e-06 | HP6: 0.0138 | HQ6: 1.41e-05 | HR6: 0.0014 | HS6: 7.86e-06 | HT6: 0.0138 | HU6: 1.54e-05 | HV6: 0.00012 | HW6: 0.0138 | HX6: 8.41e-06 | HY6: 8.15 | HZ6: 0.0586 | IA6: 80.8 | ID6: =IA6*7 -> 565.6 | IE6: =IB6*7 -> 0 | IF6: =IC6*7 -> 0 | IG6: 0.000568 | IH6: 0.00343 | II6: 0.0151 | IJ6: 0.00308 | IK6: 2.66 | IL6: -0.0339 | IM6: -0.694 | IN6: -0.0613 | IO6: -0.0354 | IP6: -0.00498 | IQ6: -0.041229824 | IR6: 8.5173392e-05 | IS6: 0.00051387771 | IT6: 0.010894595 | IU6: 0.00079502814 | IV6: 2.3774932 | IW6: 0.0034 | IX6: 0.0205 | IY6: 0.00366 | IZ6: 0.00387
A7: EF 3.0 Climate Change, fossil [kg CO2 eq.] | B7: 19 | C7: 0.254 | D7: 0.0523 | E7: 2.16 | F7: 1.68 | G7: 0.229 | H7: 5.37 | J7: 0.217 | K7: 0.0536 | M7: 0.325 | N7: 21.6 | P7: 0.217 | Q7: 0.0552 | R7: -0.0418 | S7: 3.98 | T7: 0.262 | U7: 0.217 | W7: 13.9 | X7: 0.217 | Z7: 0.0328 | AA7: 0.217 | AC7: 3.94 | AD7: 3.8 | AE7: 9.12 | AF7: 8.67e-05 | AG7: 0.217 | AI7: 0.0536 | AJ7: 10.4 | AK7: 0.554 | AL7: 13.7 | AM7: 1.03 | AO7: 0.079999591 | AP7: 27.4 | AQ7: 1.63 | AR7: 3.19 | AS7: 2.1 | AT7: 1.06 | AU7: 0.0732 | AV7: 0.0787 | AW7: -0.000458 | AX7: 0.334 | AY7: 0.243 | AZ7: 0.0711 | BA7: 0.0114 | BB7: 0.552 | BC7: -0.00697 | BD7: 0.215 | BE7: 0.145 | BF7: -0.00523 | BG7: 0.004 | BH7: 3.69 | BI7: 0.0779 | BJ7: -0.0335 | BL7: 0.411 | BM7: 0.221 | BN7: 0.444 | BO7: -0.00697 | BQ7: 0.074 | BR7: 0.0455 | BS7: 0.0195 | BT7: 3.2 | BU7: -0.0303 | BW7: 0.311 | BX7: 0.163 | BY7: 3.13 | BZ7: -0.0335 | CB7: 0.371 | CC7: 0.0325 | CD7: 0.052 | CE7: 4 | CF7: -0.0335 | CH7: 0.407 | CI7: 0.039 | CJ7: 0.143 | CK7: 0.0652 | CL7: 1.34 | CM7: 2.18 | CN7: 0.045 | CO7: 0.357 | CP7: 0.021816653 | CQ7: 0.0587 | CR7: 2.45 | CS7: 0.0426 | CT7: -0.000405 | CU7: 0.126 | CV7: 0.984 | CW7: 21.3 | CX7: -6.99 | CY7: 4.81 | CZ7: 0.747 | DA7: 36.8 | DB7: 0.295 | DC7: 0.00127 | DD7: 0.0183 | DE7: -9.67e-08 | DF7: 0.819 | DG7: 0.052 | DH7: 0.169 | DI7: 152 | DJ7: 1.72 | DK7: 2.2 | DL7: 0.103 | DM7: 0.284 | DN7: -0.00214 | DO7: 0.0142 | DP7: 1.36 | DQ7: 0.128 | DR7: 0.826 | DS7: 61.9 | DT7: 0.0145 | DU7: 0.0207 | DV7: 2.91 | DW7: 0.0739 | DX7: -0.00214 | DY7: 0.664 | DZ7: 4.4 | EA7: 0.00621 | EB7: 155 | EC7: 61.9 | ED7: 4.67 | EE7: 5.24 | EF7: 0.199 | EG7: 0.652 | EH7: -0.105 | EI7: 158 | EJ7: 0.39 | EK7: 3.83 | EL7: 0.0575 | EM7: 4.24 | EN7: 39.7 | EO7: 0.0497 | EP7: 0.117 | EQ7: 0.189 | ER7: -1.39 | ES7: 0.255 | ET7: 159 | EU7: 0.778 | EV7: 3.36 | EW7: 0.0522 | EX7: 0.956 | EY7: 1.85 | EZ7: 0.00854 | FB7: 0.214 | FC7: 58.679998 | FD7: 15.748903 | FE7: 0.2973252 | FF7: 0.34518342 | FG7: 0.051226126 | FH7: 0.0609 | FI7: 0.124 | FJ7: 0.252 | FK7: -0.000195 | FL7: 0.00466 | FM7: 0.164 | FN7: 3.99 | FO7: 0.261 | FP7: 0.00376 | FQ7: 0.0247 | FR7: -0.0183 | FT7: 0.0342 | FU7: 13.2 | FV7: 0.0803 | FW7: -9.67e-08 | FX7: 0.0544 | FY7: 0.0455 | FZ7: 1.07 | GA7: 0.00908 | GB7: 0.124 | GC7: 0.143 | GD7: -0.000242 | GE7: 3.76 | GF7: 1.74 | GG7: 0.057 | GH7: 0.191 | GI7: 0.143 | GJ7: -0.000242 | GK7: 4.27 | GL7: 0.039 | GM7: 9.39 | GN7: 3.75 | GO7: 0.17 | GP7: -0.662 | GQ7: 0.146 | GR7: 0.023703583 | GS7: 71.724799 | GT7: 24.856186 | GU7: 0.27957813 | GV7: 0.14544435 | GW7: 0.0404 | GX7: 0.476 | GY7: 0.284 | GZ7: -0.000367 | HA7: 0.00466 | HB7: 0.308 | HC7: 19.5 | HD7: 0.197 | HE7: 0.00199 | HF7: -0.000305 | HG7: 0.0583 | HH7: 21.5 | HI7: 5.2 | HJ7: 0.17 | HK7: 0.0609 | HL7: -0.000183 | HM7: 0.11 | HN7: 0.999 | HO7: 0.00889 | HP7: -0.00523 | HQ7: 0.00468 | HR7: 1.18 | HS7: 0.017 | HT7: -0.00523 | HU7: 0.00511 | HV7: 0.101 | HW7: -0.00523 | HX7: 0.00278 | HY7: 4.51 | HZ7: 19.4 | IA7: 8180 | IB7: 57600 | ID7: =IA7*7 -> 57260 | IE7: =IB7*7 -> 403200 | IF7: =IC7*7 -> 0 | IG7: 0.174 | IH7: 1.05 | II7: 3.06 | IJ7: 1.53 | IK7: 0.314 | IL7: -39.7 | IM7: -540 | IN7: -6.7 | IO7: -19.5 | IP7: -0.4 | IQ7: 9.9574428 | IR7: 0.026161051 | IS7: 0.15776715 | IT7: 2.2048716 | IU7: 0.39482815 | IV7: 0.28068534 | IW7: 3.33 | IX7: 20.1 | IY7: 2.92 | IZ7: 0.998
A8: EF 3.0 Climate Change, land use and land use change [kg CO2 eq.] | B8: 0.0107 | C8: -1.07e-05 | D8: 0.000432 | E8: 0.000609 | F8: 0.000322 | G8: -9.64e-06 | H8: 0.000112 | J8: -1.54e-05 | K8: 0.000443 | M8: -2.31e-05 | N8: 0.000451 | P8: -1.54e-05 | Q8: 0.000455 | R8: -5.31e-06 | T8: 0.00216 | U8: -1.54e-05 | W8: 0.000291 | X8: -1.54e-05 | Z8: 0.000271 | AA8: -1.54e-05 | AC8: 8.23e-05 | AD8: 0.00108 | AE8: 0.000251 | AF8: -6.17e-09 | AG8: -1.54e-05 | AI8: 0.000443 | AJ8: 0.0174 | AK8: 0.000922 | AL8: 0.000371 | AM8: 2.8e-05 | AO8: 2.2793532e-05 | AP8: 0.013 | AQ8: 0.0008 | AR8: 0.00124 | AS8: 0.000599 | AT8: 0.000524 | AU8: 1.96e-06 | AV8: 0.00015 | AW8: 6.03e-05 | AX8: 0.00276 | AY8: 9.41e-05 | AZ8: 2.03e-05 | BA8: 2.99e-06 | BB8: 0.000214 | BC8: -8.85e-07 | BD8: 0.00178 | BE8: 3.31e-06 | BF8: -6.63e-07 | BG8: 3.3e-05 | BH8: 0.000727 | BI8: 1.78e-06 | BJ8: -4.25e-06 | BL8: 0.00339 | BM8: 4.27e-05 | BN8: 8.75e-05 | BO8: -8.85e-07 | BQ8: 0.00061 | BR8: 8.79e-06 | BS8: 3.77e-06 | BT8: 0.00063 | BU8: -3.85e-06 | BW8: 0.00257 | BX8: 3.14e-05 | BY8: 0.000618 | BZ8: -4.25e-06 | CB8: 0.00306 | CC8: 6.28e-06 | CD8: 1.01e-05 | CE8: 0.000789 | CF8: -4.25e-06 | CH8: 0.00336 | CI8: 7.54e-06 | CJ8: 2.76e-05 | CK8: 1.86e-05 | CL8: 0.000622 | CM8: 0.000845 | CN8: 1.28e-05 | CP8: 6.0465595e-07 | CQ8: 1.16e-05 | CR8: 5.57e-05 | CS8: 1.17e-06 | CT8: 5.35e-05 | CU8: 0.00104 | CV8: 6.61e-05 | CW8: 0.00324 | CX8: -0.0188 | CY8: 9.84e-05 | CZ8: 0.00617 | DA8: 0.0143 | DB8: 8.41e-05 | DC8: 3.38e-08 | DD8: 5.04e-07 | DE8: 1.3e-08 | DF8: 0.00676 | DG8: 1.01e-05 | DH8: 4.81e-05 | DI8: 0.0711 | DJ8: 0.00049 | DK8: 0.000822 | DL8: 0.000197 | DM8: 7.83e-06 | DN8: 0.000281 | DO8: 7.34e-06 | DP8: 0.0112 | DQ8: 3.64e-05 | DR8: 1.88e-05 | DS8: 0.0305 | DT8: 4.03e-07 | DU8: 3.95e-05 | DV8: 6.64e-05 | DW8: 2.03e-06 | DX8: 0.000281 | DY8: 0.00548 | DZ8: 0.00231 | EA8: 3.25e-06 | EB8: 0.145 | EC8: 0.0521 | ED8: 0.00262 | EE8: 0.00274 | EF8: 0.000422 | EG8: 0.00119 | EH8: -1.33e-05 | EI8: 0.00329 | EJ8: 7.54e-05 | EK8: 0.00813 | EL8: 3.87e-06 | EM8: 0.00121 | EN8: 0.0188 | EO8: 6.55e-05 | EP8: 0.000224 | EQ8: 5.21e-06 | ER8: -0.00376 | ES8: 0.0021 | ET8: 0.076 | EU8: 0.000381 | EV8: 0.000956 | EW8: 9.97e-05 | EX8: 2.18e-05 | EY8: 5.11e-05 | EZ8: 5.3e-05 | FB8: 0.00177 | FC8: 0.027257385 | FD8: 0.0076241861 | FE8: 0.00014648161 | FF8: 9.834987e-05 | FG8: 1.3695489e-06 | FH8: 0.000116 | FI8: 2.83e-06 | FJ8: 6.95e-06 | FK8: 2.57e-05 | FL8: 7.69e-06 | FM8: 0.00135 | FN8: 0.00196 | FO8: 0.000129 | FP8: 8.71e-06 | FQ8: 7.05e-07 | FR8: -2.32e-06 | FT8: 0.000282 | FU8: 0.00483 | FV8: 2.29e-05 | FW8: 1.3e-08 | FX8: 0.000449 | FY8: 8.79e-06 | FZ8: 0.000601 | GA8: 5.51e-06 | GC8: 2.82e-05 | GD8: 7.53e-06 | GE8: 0.000555 | GF8: 0.000973 | GG8: 3.13e-05 | GI8: 2.82e-05 | GJ8: 7.53e-06 | GK8: 0.000565 | GL8: 7.54e-06 | GM8: 0.00364 | GN8: 0.000992 | GO8: 4.84e-05 | GP8: -0.00188 | GQ8: 0.00121 | GR8: 6.7536391e-06 | GS8: 0.032023469 | GT8: 0.0096356314 | GU8: 7.965757e-05 | GV8: 4.0310397e-06 | GW8: 7.71e-05 | GX8: 1.08e-05 | GY8: 7.83e-06 | GZ8: 4.82e-05 | HA8: 7.69e-06 | HB8: 0.00254 | HC8: 0.00755 | HD8: 5.63e-05 | HE8: 5.33e-08 | HF8: 4.02e-05 | HG8: 0.000481 | HH8: 0.00982 | HI8: 0.00194 | HJ8: 4.84e-05 | HK8: 0.000116 | HL8: 2.41e-05 | HM8: 0.00091 | HN8: 0.000387 | HO8: 2.53e-06 | HP8: -6.63e-07 | HQ8: 3.86e-05 | HR8: 0.000458 | HS8: 5.12e-06 | HT8: -6.63e-07 | HU8: 4.22e-05 | HV8: 3.91e-05 | HW8: -6.63e-07 | HX8: 2.3e-05 | HY8: 0.0302 | HZ8: 0.16 | IA8: 1.37 | ID8: =IA8*7 -> 9.59 | IE8: =IB8*7 -> 0 | IF8: =IC8*7 -> 0 | IG8: 0.000513 | IH8: 0.00309 | II8: 0.00394 | IJ8: 0.00128 | IK8: 0.00014 | IL8: -0.0747 | IM8: -0.254 | IN8: -0.00386 | IO8: -0.00179 | IP8: -0.000777 | IQ8: -0.0061017631 | IR8: 7.6867418e-05 | IS8: 0.00046348946 | IT8: 0.0028362822 | IU8: 0.00033009692 | IV8: 0.00012520957 | IW8: 0.00106 | IX8: 0.00641 | IY8: 0.00102 | IZ8: 0.000575
A9: EF 3.0 Ecotoxicity, freshwater - total [CTUe] | B9: 175 | C9: -0.219 | D9: 0.522 | E9: 3.55 | F9: 14.7 | G9: -0.121 | H9: 52.9 | I9: 41100 | J9: 6.67 | K9: 0.535 | L9: 5780 | M9: 10 | N9: 213 | O9: 5850 | P9: 6.67 | Q9: 0.55 | R9: 7.65 | S9: 18.9 | T9: 2.62 | U9: 6.67 | V9: 82100 | W9: 137 | X9: 6.67 | Y9: 6360 | Z9: 0.327 | AA9: 6.67 | AB9: 428 | AC9: 38.8 | AD9: 6.47 | AE9: 947 | AF9: 0.00267 | AG9: 6.67 | AH9: 82100 | AI9: 0.535 | AJ9: 410 | AK9: 21.7 | AL9: 1.67 | AM9: 0.126 | AN9: 0.0271 | AO9: 0.13603191 | AP9: 132 | AQ9: 7.28 | AR9: 12.9 | AS9: 3.58 | AT9: 4.72 | AU9: 1.84 | AV9: 0.487 | AW9: 0.0787 | AX9: 3.33 | AY9: 0.99 | AZ9: 0.121 | BA9: 14.9 | BB9: 7.21 | BC9: 1.23 | BD9: 2.15 | BE9: 1.95 | BF9: 0.925 | BG9: 0.0399 | BH9: 86.8 | BI9: 1.05 | BJ9: 5.92 | BK9: 44 | BL9: 4.1 | BM9: 2.86 | BN9: 10.5 | BO9: 1.23 | BP9: 26.1 | BQ9: 0.738 | BR9: 0.589 | BS9: 0.252 | BT9: 75.2 | BU9: 5.37 | BV9: 57 | BW9: 3.11 | BX9: 2.1 | BY9: 73.8 | BZ9: 5.92 | CA9: 106 | CB9: 3.7 | CC9: 0.421 | CD9: 0.673 | CE9: 94.3 | CF9: 5.92 | CG9: 103 | CH9: 4.06 | CI9: 0.505 | CJ9: 1.85 | CK9: 0.111 | CL9: 6.36 | CM9: 8.81 | CN9: 0.0766 | CO9: 1.69 | CP9: 0.55212038 | CQ9: 1.38 | CR9: 32.8 | CS9: 4.43 | CT9: 0.0699 | CU9: 1.26 | CV9: 0.926 | CW9: 633 | CX9: 51.2 | CY9: 155 | CZ9: 7.46 | DA9: 150 | DB9: 0.502 | DC9: 0.0318 | DD9: 1.9 | DE9: 1.7e-05 | DF9: 8.17 | DG9: 0.673 | DH9: 0.287 | DI9: 723 | DJ9: 2.92 | DK9: 8.77 | DL9: 0.639 | DM9: 29.5 | DN9: 0.367 | DO9: 0.215 | DP9: 13.6 | DQ9: 0.217 | DR9: 11.1 | DS9: 297 | DT9: 0.368 | DU9: 0.128 | DV9: 39.1 | DW9: 7.67 | DX9: 0.367 | DY9: 6.62 | DZ9: 7.42 | EA9: 0.0105 | EB9: 702 | EC9: 299 | ED9: 18.7 | EE9: 8.83 | EF9: 1.21 | EG9: 59.7 | EH9: 19.1 | EI9: 1550 | EJ9: 5.05 | EK9: 23.3 | EL9: 0.0541 | EM9: 7.22 | EN9: 181 | EO9: 0.635 | EP9: 0.726 | EQ9: 19.7 | ER9: 9.48 | ES9: 2.54 | ET9: 717 | EU9: 35.2 | EV9: 5.71 | EW9: 0.323 | EX9: 12.8 | EY9: 193 | EZ9: 0.235 | FA9: 0.288 | FB9: 2.14 | FC9: 261.62689 | FD9: 71.654348 | FE9: 1.3195784 | FF9: 0.58695251 | FG9: 1.2872825 | FH9: 0.377 | FI9: 1.67 | FJ9: 26.2 | FK9: 0.0336 | FL9: 0.0283 | FM9: 1.64 | FN9: 17.7 | FO9: 1.16 | FP9: 0.0257 | FQ9: 2.58 | FR9: 2.92 | FS9: 26.1 | FT9: 0.341 | FU9: 89.3 | FV9: 0.136 | FW9: 1.7e-05 | FX9: 0.543 | FY9: 0.589 | FZ9: 4.28 | GA9: 0.04 | GB9: 0.588 | GC9: 3.37 | GD9: 0.012 | GE9: 37.1 | GF9: 6.93 | GG9: 0.0999 | GH9: 0.905 | GI9: 3.37 | GJ9: 0.012 | GK9: 42.1 | GL9: 0.505 | GM9: 38 | GN9: 17.7 | GO9: 0.289 | GP9: 4.91 | GQ9: 1.46 | GR9: 0.040305752 | GS9: 303.92668 | GT9: 101.3841 | GU9: 0.47539677 | GV9: 3.6808025 | GW9: 0.25 | GX9: 6.39 | GY9: 29.5 | GZ9: 0.063 | HA9: 0.0283 | HB9: 3.08 | HC9: 78.7 | HD9: 0.336 | HE9: 0.0501 | HF9: 0.0524 | HG9: 0.581 | HH9: 111 | HI9: 20.9 | HJ9: 0.289 | HK9: 0.377 | HL9: 0.0315 | HM9: 1.1 | HN9: 4.04 | HO9: 0.0151 | HP9: 0.925 | HQ9: 0.0467 | HR9: 4.77 | HS9: 0.0301 | HT9: 0.925 | HU9: 0.051 | HV9: 0.408 | HW9: 0.925 | HX9: 0.0278 | HY9: 183 | HZ9: 193 | IA9: 648000 | IB9: 150 | IC9: 234 | ID9: =IA9*7 -> 4536000 | IE9: =IB9*7 -> 1050 | IF9: =IC9*7 -> 1638 | IG9: 1.33 | IH9: 248 | II9: 19.6 | IJ9: 21.2 | IK9: 5.73 | IL9: -263 | IM9: -2340 | IN9: -78400 | IO9: -948 | IP9: -3.89 | IQ9: -30.256845 | IR9: 0.19975314 | IS9: 37.206798 | IT9: 14.108157 | IU9: 5.4688923 | IV9: 5.1279586 | IW9: 7.8 | IX9: 47 | IY9: 7.23 | IZ9: 3.08
A10: EF 3.0 Ecotoxicity, freshwater inorganics [CTUe] | B10: 60.8 | C10: -0.0174 | D10: 0.506 | E10: 2.72 | F10: 13.5 | G10: -0.0151 | H10: 51.6 | J10: 0.033 | K10: 0.518 | M10: 0.0495 | N10: 208 | P10: 0.033 | Q10: 0.533 | R10: 0.056 | S10: 17.8 | T10: 2.53 | U10: 0.033 | W10: 134 | X10: 0.033 | Z10: 0.317 | AA10: 0.033 | AC10: 37.9 | AD10: 4.75 | AE10: 18 | AF10: 1.32e-05 | AG10: 0.033 | AI10: 0.518 | AJ10: 54.7 | AK10: 2.9 | AL10: 1.33 | AM10: 0.1 | AO10: 0.099972406 | AP10: 79.1 | AQ10: 5.09 | AR10: 8.95 | AS10: 2.63 | AT10: 3.29 | AU10: 0.0372 | AV10: 0.33 | AW10: 0.101 | AX10: 3.23 | AY10: 0.69 | AZ10: 0.0889 | BA10: 0.0414 | BB10: 5.93 | BC10: 0.00934 | BD10: 2.08 | BE10: 1.57 | BF10: 0.00701 | BG10: 0.0386 | BH10: 16.7 | BI10: 0.841 | BJ10: 0.0448 | BL10: 3.97 | BM10: 1.56 | BN10: 2.01 | BO10: 0.00934 | BQ10: 0.715 | BR10: 0.32 | BS10: 0.137 | BT10: 14.4 | BU10: 0.0406 | BW10: 3.01 | BX10: 1.14 | BY10: 14.2 | BZ10: 0.0448 | CB10: 3.59 | CC10: 0.229 | CD10: 0.366 | CE10: 18.1 | CF10: 0.0448 | CH10: 3.93 | CI10: 0.275 | CJ10: 1.01 | CK10: 0.0815 | CL10: 3.72 | CM10: 6.12 | CN10: 0.0563 | CO10: 1.6 | CP10: 0.011211313 | CQ10: 0.265 | CR10: 26.4 | CS10: 0.084 | CT10: 0.09 | CU10: 1.22 | CV10: 0.565 | CW10: 310 | CX10: -24.5 | CY10: 147 | CZ10: 7.22 | DA10: 105 | DB10: 0.369 | DC10: 0.000644 | DD10: 0.0361 | DE10: 2.19e-05 | DF10: 7.91 | DG10: 0.366 | DH10: 0.211 | DI10: 428 | DJ10: 2.15 | DK10: 6.09 | DL10: 0.433 | DM10: 0.56 | DN10: 0.473 | DO10: 0.18 | DP10: 13.1 | DQ10: 0.159 | DR10: 8.9 | DS10: 192 | DT10: 0.00747 | DU10: 0.0868 | DV10: 31.4 | DW10: 0.146 | DX10: 0.473 | DY10: 6.41 | DZ10: 5.89 | EA10: 0.00831 | EB10: 450 | EC10: 183 | ED10: 13.2 | EE10: 7.01 | EF10: 0.832 | EG10: 1.42 | EH10: 0.14 | EI10: 1520 | EJ10: 2.75 | EK10: 16 | EL10: 0.033 | EM10: 5.3 | EN10: 115 | EO10: 0.556 | EP10: 0.492 | EQ10: 0.373 | ER10: -4.9 | ES10: 2.46 | ET10: 466 | EU10: 2.39 | EV10: 4.2 | EW10: 0.219 | EX10: 10.3 | EY10: 3.65 | EZ10: 0.273 | FB10: 2.07 | FC10: 163.21413 | FD10: 47.226984 | FE10: 0.91980822 | FF10: 0.43136242 | FG10: 0.026056228 | FH10: 0.255 | FI10: 1.34 | FJ10: 0.497 | FK10: 0.0432 | FL10: 0.0185 | FM10: 1.58 | FN10: 12.3 | FO10: 0.808 | FP10: 0.0173 | FQ10: 0.0491 | FR10: 0.0245 | FT10: 0.33 | FU10: 73.7 | FV10: 0.1 | FW10: 2.19e-05 | FX10: 0.526 | FY10: 0.32 | FZ10: 3.02 | GA10: 0.0281 | GB10: 0.556 | GC10: 0.646 | GD10: 0.00948 | GE10: 36.2 | GF10: 4.89 | GG10: 0.0792 | GH10: 0.856 | GI10: 0.646 | GJ10: 0.00948 | GK10: 41.1 | GL10: 0.275 | GM10: 26.4 | GN10: 11.5 | GO10: 0.212 | GP10: -2.45 | GQ10: 1.41 | GR10: 0.029621453 | GS10: 185.15703 | GT10: 70.662652 | GU10: 0.34937801 | GV10: 0.074742085 | GW10: 0.169 | GX10: 5.13 | GY10: 0.56 | GZ10: 0.0811 | HA10: 0.0185 | HB10: 2.98 | HC10: 54.6 | HD10: 0.247 | HE10: 0.00101 | HF10: 0.0676 | HG10: 0.563 | HH10: 57.9 | HI10: 14.6 | HJ10: 0.212 | HK10: 0.255 | HL10: 0.0405 | HM10: 1.06 | HN10: 2.8 | HO10: 0.0111 | HP10: 0.00701 | HQ10: 0.0452 | HR10: 3.31 | HS10: 0.0221 | HT10: 0.00701 | HU10: 0.0494 | HV10: 0.283 | HW10: 0.00701 | HX10: 0.0269 | HY10: 134 | HZ10: 187 | IA10: 633000 | IB10: 1.08 | ID10: =IA10*7 -> 4431000 | IE10: =IB10*7 -> 7.56 | IF10: =IC10*7 -> 0 | IG10: 1.24 | IH10: 7.46 | II10: 15.1 | IJ10: 6.28 | IK10: 5.37 | IL10: -165 | IM10: -1640 | IN10: -21.3 | IO10: -235 | IP10: -1.91 | IQ10: -16.101655 | IR10: 0.18566866 | IS10: 1.1195483 | IT10: 10.889769 | IU10: 1.6209045 | IV10: 4.8062972 | IW10: 4.73 | IX10: 28.5 | IY10: 4.32 | IZ10: 1.61
A11: EF 3.0 Ecotoxicity, freshwater metals [CTUe] | B11: 113 | C11: -0.206 | D11: 0.0104 | E11: 0.811 | F11: 1.1 | G11: -0.189 | H11: 0.82 | J11: -0.515 | K11: 0.0107 | M11: -0.773 | N11: 3.3 | P11: -0.515 | Q11: 0.011 | R11: -0.343 | S11: 0.691 | T11: 0.0521 | U11: -0.515 | W11: 2.13 | X11: -0.515 | Z11: 0.00651 | AA11: -0.515 | AC11: 0.602 | AD11: 1.68 | AE11: 348 | AF11: -0.000206 | AG11: -0.515 | AI11: 0.0107 | AJ11: 355 | AK11: 18.8 | AL11: 0.307 | AM11: 0.0232 | AO11: 0.035363161 | AP11: 34.3 | AQ11: 1.94 | AR11: 3.51 | AS11: 0.93 | AT11: 1.27 | AU11: 1.79 | AV11: 0.155 | AW11: -0.0577 | AX11: 0.0664 | AY11: 0.267 | AZ11: 0.0314 | BA11: 14.8 | BB11: 0.534 | BC11: -0.0572 | BD11: 0.0427 | BE11: 0.0403 | BF11: -0.0429 | BG11: 0.000794 | BH11: 70.1 | BI11: 0.0216 | BJ11: -0.274 | BL11: 0.0816 | BM11: 1.29 | BN11: 8.43 | BO11: -0.0572 | BQ11: 0.0147 | BR11: 0.265 | BS11: 0.114 | BT11: 60.7 | BU11: -0.249 | BW11: 0.0619 | BX11: 0.947 | BY11: 59.5 | BZ11: -0.274 | CB11: 0.0737 | CC11: 0.189 | CD11: 0.303 | CE11: 76.1 | CF11: -0.274 | CH11: 0.0808 | CI11: 0.227 | CJ11: 0.834 | CK11: 0.0288 | CL11: 1.72 | CM11: 2.4 | CN11: 0.0199 | CO11: 0.062 | CP11: 0.53790778 | CQ11: 1.12 | CR11: 0.678 | CS11: 1.63 | CT11: -0.0512 | CU11: 0.0251 | CV11: 0.355 | CW11: 309 | CX11: -35.1 | CY11: 8.11 | CZ11: 0.148 | DA11: 40.4 | DB11: 0.131 | DC11: 0.031 | DD11: 0.699 | DE11: -1.24e-05 | DF11: 0.163 | DG11: 0.303 | DH11: 0.0747 | DI11: 193 | DJ11: 0.76 | DK11: 2.38 | DL11: 0.203 | DM11: 10.9 | DN11: -0.269 | DO11: 0.0339 | DP11: 0.27 | DQ11: 0.0564 | DR11: 0.229 | DS11: 74 | DT11: 0.359 | DU11: 0.0408 | DV11: 0.809 | DW11: 2.82 | DX11: -0.269 | DY11: 0.132 | DZ11: 1.47 | EA11: 0.00207 | EB11: 170 | EC11: 68.9 | ED11: 4.87 | EE11: 1.75 | EF11: 0.373 | EG11: 21.7 | EH11: -0.858 | EI11: 24.1 | EJ11: 2.27 | EK11: 7.19 | EL11: 0.0208 | EM11: 1.88 | EN11: 49.8 | EO11: 0.0757 | EP11: 0.231 | EQ11: 7.23 | ER11: -6.98 | ES11: 0.0506 | ET11: 198 | EU11: 0.937 | EV11: 1.48 | EW11: 0.103 | EX11: 0.265 | EY11: 70.8 | EZ11: -0.04 | FB11: 0.0426 | FC11: 75.452227 | FD11: 19.257606 | FE11: 0.35538539 | FF11: 0.15258549 | FG11: 1.2542237 | FH11: 0.12 | FI11: 0.0345 | FJ11: 9.63 | FK11: -0.0246 | FL11: 0.00973 | FM11: 0.0326 | FN11: 4.77 | FO11: 0.312 | FP11: 0.00837 | FQ11: 0.95 | FR11: -0.15 | FT11: 0.00679 | FU11: 13.8 | FV11: 0.0355 | FW11: -1.24e-05 | FX11: 0.0108 | FY11: 0.265 | FZ11: 1.12 | GA11: 0.0105 | GB11: 0.0216 | GC11: 2.72 | GD11: -0.00762 | GE11: 0.578 | GF11: 1.81 | GG11: 0.0198 | GH11: 0.0332 | GI11: 2.72 | GJ11: -0.00762 | GK11: 0.655 | GL11: 0.227 | GM11: 10.3 | GN11: 5.68 | GO11: 0.0751 | GP11: -3.53 | GQ11: 0.029 | GR11: 0.010477974 | GS11: 96.385027 | GT11: 27.326749 | GU11: 0.12358521 | GV11: 3.5860518 | GW11: 0.0795 | GX11: 0.132 | GY11: 10.9 | GZ11: -0.0461 | HA11: 0.00973 | HB11: 0.0612 | HC11: 21.4 | HD11: 0.0873 | HE11: 0.0488 | HF11: -0.0384 | HG11: 0.0116 | HH11: 28.2 | HI11: 5.64 | HJ11: 0.0751 | HK11: 0.12 | HL11: -0.0231 | HM11: 0.0219 | HN11: 1.1 | HO11: 0.00393 | HP11: -0.0429 | HQ11: 0.000929 | HR11: 1.3 | HS11: 0.00786 | HT11: -0.0429 | HU11: 0.00101 | HV11: 0.111 | HW11: -0.0429 | HX11: 0.000552 | HY11: -32.1 | HZ11: 3.85 | IA11: 10100 | ID11: =IA11*7 -> 70700 | IE11: =IB11*7 -> 0 | IF11: =IC11*7 -> 0 | IG11: 0.0839 | IH11: 241 | II11: 4.37 | IJ11: 2.64 | IK11: 0.158 | IL11: -96.8 | IM11: -618 | IN11: -39.4 | IO11: -359 | IP11: -1.99 | IQ11: -16.770035 | IR11: 0.012579564 | IS11: 36.078176 | IT11: 3.1420102 | IU11: 0.68225324 | IV11: 0.14154558 | IW11: 3.03 | IX11: 18.3 | IY11: 2.88 | IZ11: 1.46
A12: EF 3.0 Ecotoxicity, freshwater organics [CTUe] | B12: 0.81 | C12: 0.00454 | D12: 0.00623 | E12: 0.0191 | F12: 0.153 | G12: 0.00419 | H12: 0.419 | J12: 0.0131 | K12: 0.00638 | M12: 0.0197 | N12: 1.69 | P12: 0.0131 | Q12: 0.00657 | R12: 0.00956 | S12: 0.333 | T12: 0.0312 | U12: 0.0131 | W12: 1.09 | X12: 0.0131 | Z12: 0.0039 | AA12: 0.0131 | AC12: 0.308 | AD12: 0.0331 | AE12: 581 | AF12: 5.26e-06 | AG12: 0.0131 | AI12: 0.00638 | AJ12: 0.418 | AK12: 0.0222 | AL12: 0.0355 | AM12: 0.00268 | AO12: 0.00069634584 | AP12: 3.6 | AQ12: 0.243 | AR12: 0.436 | AS12: 0.0183 | AT12: 0.159 | AU12: 0.01 | AV12: 0.00179 | AW12: 0.00153 | AX12: 0.0398 | AY12: 0.0332 | AZ12: 0.000619 | BA12: 0.0781 | BB12: 0.04 | BC12: 0.00159 | BD12: 0.0256 | BE12: 0.0167 | BF12: 0.00119 | BG12: 0.000476 | BH12: 0.112 | BI12: 0.00895 | BJ12: 0.00764 | BL12: 0.0489 | BM12: 0.0163 | BN12: 0.0134 | BO12: 0.00159 | BQ12: 0.0088 | BR12: 0.00336 | BS12: 0.00144 | BT12: 0.0967 | BU12: 0.00693 | BW12: 0.0371 | BX12: 0.012 | BY12: 0.0948 | BZ12: 0.00764 | CB12: 0.0442 | CC12: 0.0024 | CD12: 0.00384 | CE12: 0.121 | CF12: 0.00764 | CH12: 0.0484 | CI12: 0.00288 | CJ12: 0.0106 | CK12: 0.000567 | CL12: 0.163 | CM12: 0.298 | CN12: 0.000392 | CO12: 0.0298 | CP12: 0.003001286 | CQ12: 0.00178 | CR12: 0.281 | CS12: 2.72 | CT12: 0.00136 | CU12: 0.015 | CV12: 0.00557 | CW12: 2.71 | CX12: -0.196 | CY12: 0.187 | CZ12: 0.089 | DA12: 5.02 | DB12: 0.00257 | DC12: 0.000173 | DD12: 1.17 | DE12: 3.3e-07 | DF12: 0.0975 | DG12: 0.00384 | DH12: 0.00147 | DI12: 19 | DJ12: 0.015 | DK12: 0.297 | DL12: 0.00234 | DM12: 18.1 | DN12: 0.00715 | DO12: 0.00135 | DP12: 0.162 | DQ12: 0.00111 | DR12: 0.0948 | DS12: 9.24 | DT12: 0.002 | DU12: 0.000469 | DV12: 0.335 | DW12: 4.71 | DX12: 0.00715 | DY12: 0.079 | DZ12: 0.0632 | EA12: 8.92e-05 | EB12: 19.7 | EC12: 8.22 | ED12: 0.633 | EE12: 0.0752 | EF12: 0.00453 | EG12: 36.7 | EH12: 0.0239 | EI12: 12.3 | EJ12: 0.0288 | EK12: 0.0873 | EL12: 0.000326 | EM12: 0.0369 | EN12: 5.23 | EO12: 0.00305 | EP12: 0.00266 | EQ12: 12.1 | ER12: -0.04 | ES12: 0.0303 | ET12: 21.5 | EU12: 0.114 | EV12: 0.0292 | EW12: 0.00118 | EX12: 0.11 | EY12: 118 | EZ12: 0.00231 | FB12: 0.0255 | FC12: 7.1523969 | FD12: 2.2199141 | FE12: 0.044384812 | FF12: 0.0030046033 | FG12: 0.0070025697 | FH12: 0.00138 | FI12: 0.0143 | FJ12: 16.1 | FK12: 0.000654 | FL12: 9.89e-05 | FM12: 0.0195 | FN12: 0.595 | FO12: 0.039 | FP12: -2.23e-05 | FQ12: 1.58 | FR12: 0.00417 | FT12: 0.00407 | FU12: 1.71 | FV12: 0.000699 | FW12: 3.3e-07 | FX12: 0.00647 | FY12: 0.00336 | FZ12: 0.145 | GA12: 0.00135 | GB12: 0.0104 | GC12: 0.00433 | GD12: 0.000181 | GE12: 0.296 | GF12: 0.235 | GG12: 0.000845 | GH12: 0.016 | GI12: 0.00433 | GJ12: 0.000181 | GK12: 0.336 | GL12: 0.00288 | GM12: 1.28 | GN12: 0.464 | GO12: 0.00148 | GP12: -0.0192 | GQ12: 0.0174 | GR12: 0.00020632469 | GS12: 7.4841316 | GT12: 3.3946964 | GU12: 0.0024335507 | GV12: 0.020008573 | GW12: 0.000915 | GX12: 0.0547 | GY12: 18.1 | GZ12: 0.00123 | HA12: 9.89e-05 | HB12: 0.0367 | HC12: 2.66 | HD12: 0.00172 | HE12: 0.000273 | HF12: 0.00102 | HG12: 0.00694 | HH12: 2.46 | HI12: 0.702 | HJ12: 0.00148 | HK12: 0.00138 | HL12: 0.000613 | HM12: 0.0131 | HN12: 0.136 | HO12: 7.74e-05 | HP12: 0.00119 | HQ12: 0.000557 | HR12: 0.161 | HS12: 0.000152 | HT12: 0.00119 | HU12: 0.000608 | HV12: 0.0138 | HW12: 0.00119 | HX12: 0.000331 | HY12: 1.38 | HZ12: 2.31 | IA12: 4990 | IB12: 149 | ID12: =IA12*7 -> 34930 | IE12: =IB12*7 -> 1043 | IF12: =IC12*7 -> 0 | IG12: 0.01 | IH12: 0.0605 | II12: 0.106 | IJ12: 12.3 | IK12: 0.201 | IL12: -1.01 | IM12: -79.5 | IN12: -0.289 | IO12: -349 | IP12: 0.0241 | IQ12: 2.6148452 | IR12: 0.001504913 | IS12: 0.0090737989 | IT12: 0.076377004 | IU12: 3.1657346 | IV12: 0.18011578 | IW12: 0.0311 | IX12: 0.187 | IY12: 0.0278 | IZ12: 0.009
A13: EF 3.0 Eutrophication, freshwater [kg P eq.] | B13: 3.12e-05 | C13: 3.33e-07 | D13: 1.57e-07 | E13: 8.79e-07 | F13: 2.05e-06 | G13: 3.26e-06 | H13: 8.69e-07 | I13: 0.605 | J13: 0.000267 | K13: 1.61e-07 | L13: 0.22 | M13: 0.0004 | N13: 3.5e-06 | O13: 0.119 | P13: 0.000267 | Q13: 1.65e-07 | R13: 0.000296 | S13: 4.41e-05 | T13: 7.87e-07 | U13: 0.000267 | V13: 0.0279 | W13: 2.26e-06 | X13: 0.000267 | Y13: 0.0931 | Z13: 9.83e-08 | AA13: 0.000267 | AB13: 0.0061 | AC13: 6.39e-07 | AD13: 1.57e-06 | AE13: 0.000321 | AF13: 1.07e-07 | AG13: 0.000267 | AH13: 1.21 | AI13: 1.61e-07 | AJ13: 3.59e-05 | AK13: 1.9e-06 | AL13: 5.55e-07 | AM13: 4.19e-08 | AN13: 3.12e-06 | AO13: 3.3006803e-08 | AP13: 0.000107 | AQ13: 7.87e-07 | AR13: 1.35e-06 | AS13: 8.68e-07 | AT13: 5.11e-07 | AU13: 2.21e-06 | AV13: 1.05e-07 | AW13: 1.6e-06 | AX13: 1e-06 | AY13: 1.04e-07 | AZ13: 2.93e-08 | BA13: 5.13e-08 | BB13: 1.04e-05 | BC13: 5.48e-05 | BD13: 6.45e-07 | BE13: 8.05e-06 | BF13: 4.11e-05 | BG13: 1.2e-08 | BH13: 2.47e-05 | BI13: 4.31e-06 | BJ13: 0.000263 | BK13: 0.00176 | BL13: 1.23e-06 | BM13: 6.11e-07 | BN13: 2.97e-06 | BO13: 5.48e-05 | BP13: 0.00104 | BQ13: 2.22e-07 | BR13: 1.26e-07 | BS13: 5.39e-08 | BT13: 2.14e-05 | BU13: 0.000239 | BV13: 0.00228 | BW13: 9.34e-07 | BX13: 4.5e-07 | BY13: 2.1e-05 | BZ13: 0.000263 | CA13: 0.00424 | CB13: 1.11e-06 | CC13: 8.99e-08 | CD13: 1.44e-07 | CE13: 2.68e-05 | CF13: 0.000263 | CG13: 0.00412 | CH13: 1.22e-06 | CI13: 1.08e-07 | CJ13: 3.96e-07 | CK13: 2.69e-08 | CL13: 5.41e-06 | CM13: 9.23e-07 | CN13: 1.86e-08 | CO13: 3.95e-06 | CP13: 6.6317929e-07 | CQ13: 3.93e-07 | CR13: 0.000135 | CS13: 1.5e-06 | CT13: 1.42e-06 | CU13: 3.79e-07 | CV13: 2.55e-07 | CW13: 0.00145 | CX13: 0.00323 | CY13: 9.03e-05 | CZ13: 2.24e-06 | DA13: 1.57e-05 | DB13: 1.22e-07 | DC13: 3.82e-08 | DD13: 6.44e-07 | DE13: 3.46e-10 | DF13: 2.46e-06 | DG13: 1.44e-07 | DH13: 6.97e-08 | DI13: 0.000589 | DJ13: 7.09e-07 | DK13: 9.14e-07 | DL13: 1.37e-07 | DM13: 9.99e-06 | DN13: 7.46e-06 | DO13: 2.29e-08 | DP13: 4.07e-06 | DQ13: 5.27e-08 | DR13: 4.57e-05 | DS13: 0.000171 | DT13: 4.42e-07 | DU13: 2.75e-08 | DV13: 0.000161 | DW13: 2.6e-06 | DX13: 7.46e-06 | DY13: 1.99e-06 | DZ13: 6e-06 | EA13: 8.47e-09 | EB13: 0.000493 | EC13: 0.000283 | ED13: 2.27e-06 | EE13: 7.14e-06 | EF13: 2.78e-07 | EG13: 2.07e-05 | EH13: 0.00074 | EI13: 2.56e-05 | EJ13: 1.08e-06 | EK13: 5.35e-06 | EL13: 1.49e-08 | EM13: 1.75e-06 | EN13: 8.99e-05 | EO13: 1.39e-07 | EP13: 1.56e-07 | EQ13: 6.66e-06 | ER13: 0.000639 | ES13: 7.65e-07 | ET13: 0.000278 | EU13: 0.000198 | EV13: 1.39e-06 | EW13: 6.93e-08 | EX13: 5.29e-05 | EY13: 6.52e-05 | EZ13: 3.01e-07 | FA13: 1.15e-05 | FB13: 6.43e-07 | FC13: 0.00012948738 | FD13: 2.6137722e-05 | FE13: 1.4286995e-07 | FF13: 1.4241824e-07 | FG13: 1.5473379e-06 | FH13: 8.09e-08 | FI13: 6.88e-06 | FJ13: 8.87e-06 | FK13: 6.82e-07 | FL13: 1e-08 | FM13: 4.92e-07 | FN13: 1.92e-06 | FO13: 1.26e-07 | FP13: 5.91e-09 | FQ13: 8.74e-07 | FR13: 0.000184 | FS13: 0.00104 | FT13: 1.03e-07 | FU13: 8.74e-06 | FV13: 3.31e-08 | FW13: 3.46e-10 | FX13: 1.63e-07 | FY13: 1.26e-07 | FZ13: 5.2e-07 | GA13: 4.73e-09 | GB13: 1.38e-06 | GC13: 9.57e-07 | GD13: 4.14e-07 | GE13: 7.74e-07 | GF13: 8.41e-07 | GG13: 8.09e-08 | GH13: 2.12e-06 | GI13: 9.57e-07 | GJ13: 4.14e-07 | GK13: 8.56e-07 | GL13: 1.08e-07 | GM13: 3.98e-06 | GN13: 1.31e-06 | GO13: 7.01e-08 | GP13: 0.000322 | GQ13: 4.38e-07 | GR13: 9.7797934e-09 | GS13: 0.00013328807 | GT13: 1.0600109e-05 | GU13: 1.1535034e-07 | GV13: 4.4211953e-06 | GW13: 5.36e-08 | GX13: 2.64e-05 | GY13: 9.99e-06 | GZ13: 1.28e-06 | HA13: 1e-08 | HB13: 9.25e-07 | HC13: 8.24e-06 | HD13: 8.15e-08 | HE13: 6.02e-08 | HF13: 1.06e-06 | HG13: 1.75e-07 | HH13: 0.000153 | HI13: 2.18e-06 | HJ13: 7.01e-08 | HK13: 8.09e-08 | HL13: 6.4e-07 | HM13: 3.31e-07 | HN13: 4.23e-07 | HO13: 3.67e-09 | HP13: 4.11e-05 | HQ13: 1.4e-08 | HR13: 5e-07 | HS13: 7.27e-09 | HT13: 4.11e-05 | HU13: 1.53e-08 | HV13: 4.27e-08 | HW13: 4.11e-05 | HX13: 8.34e-09 | HY13: 0.00313 | HZ13: 5.81e-05 | IA13: 0.0107 | IC13: 0.0099 | ID13: =IA13*7 -> 0.0749 | IE13: =IB13*7 -> 0 | IF13: =IC13*7 -> 0.0693 | IG13: 2.93e-07 | IH13: 1.77e-06 | II13: 5.51e-06 | IJ13: 0.000283 | IK13: 3.16e-05 | IL13: -5.2e-05 | IM13: -0.000251 | IN13: -0.798 | IO13: -0.000984 | IP13: -1.46e-06 | IQ13: -1.1989597e-05 | IR13: 4.3912704e-08 | IS13: 2.6486541e-07 | IT13: 3.9671371e-06 | IU13: 7.2898975e-05 | IV13: 2.8310657e-05 | IW13: 2.3e-06 | IX13: 1.39e-05 | IY13: 2.18e-06 | IZ13: 1.29e-06
A14: EF 3.0 Eutrophication, marine [kg N eq.] | B14: 0.00788 | C14: 0.00013 | D14: 0.000155 | E14: 0.0013 | F14: 0.00109 | G14: 0.000127 | H14: 0.00971 | I14: 0.494 | J14: 0.000972 | K14: 0.000158 | L14: 0.732 | M14: 0.00146 | N14: 0.0391 | O14: 0.258 | P14: 0.000972 | Q14: 0.000163 | R14: 0.000935 | S14: 0.00369 | T14: 0.000775 | U14: 0.000972 | V14: 0.0234 | W14: 0.0252 | X14: 0.000972 | Y14: 0.0749 | Z14: 9.69e-05 | AA14: 0.000972 | AB14: 0.00699 | AC14: 0.00713 | AD14: 0.00231 | AE14: 0.00668 | AF14: 3.89e-07 | AG14: 0.000972 | AH14: 0.988 | AI14: 0.000158 | AJ14: 0.00731 | AK14: 0.000388 | AL14: 0.00418 | AM14: 0.000315 | AN14: 4.12e-06 | AO14: 4.8478515e-05 | AP14: 0.0199 | AQ14: 0.00107 | AR14: 0.00203 | AS14: 0.00127 | AT14: 0.0007 | AU14: 4.77e-05 | AV14: 9e-05 | AW14: 3.98e-05 | AX14: 0.000987 | AY14: 0.000154 | AZ14: 4.31e-05 | BA14: 1.23e-05 | BB14: 0.000305 | BC14: 0.000155 | BD14: 0.000636 | BE14: 0.000103 | BF14: 0.000116 | BG14: 1.18e-05 | BH14: 0.00245 | BI14: 5.5e-05 | BJ14: 0.000743 | BK14: 0.0351 | BL14: 0.00121 | BM14: 0.000145 | BN14: 0.000294 | BO14: 0.000155 | BP14: 0.0208 | BQ14: 0.000218 | BR14: 2.98e-05 | BS14: 1.28e-05 | BT14: 0.00212 | BU14: 0.000673 | BV14: 0.0455 | BW14: 0.00092 | BX14: 0.000106 | BY14: 0.00208 | BZ14: 0.000743 | CA14: 0.0846 | CB14: 0.0011 | CC14: 2.13e-05 | CD14: 3.4e-05 | CE14: 0.00266 | CF14: 0.000743 | CG14: 0.0823 | CH14: 0.0012 | CI14: 2.55e-05 | CJ14: 9.36e-05 | CK14: 3.95e-05 | CL14: 0.000984 | CM14: 0.00139 | CN14: 2.73e-05 | CO14: 0.000331 | CP14: 1.4146367e-05 | CQ14: 3.89e-05 | CR14: 0.00173 | CS14: 3.12e-05 | CT14: 3.53e-05 | CU14: 0.000373 | CV14: 0.000377 | CW14: 0.0167 | CX14: 0.00192 | CY14: 0.00267 | CZ14: 0.00221 | DA14: 0.0234 | DB14: 0.000179 | DC14: 8.25e-07 | DD14: 1.34e-05 | DE14: 8.57e-09 | DF14: 0.00242 | DG14: 3.4e-05 | DH14: 0.000102 | DI14: 0.111 | DJ14: 0.00104 | DK14: 0.00139 | DL14: 0.000118 | DM14: 0.000208 | DN14: 0.000186 | DO14: 6.91e-06 | DP14: 0.00401 | DQ14: 7.73e-05 | DR14: 0.000583 | DS14: 0.0431 | DT14: 9.43e-06 | DU14: 2.37e-05 | DV14: 0.00206 | DW14: 5.41e-05 | DX14: 0.000186 | DY14: 0.00196 | DZ14: 0.00235 | EA14: 3.31e-06 | EB14: 0.116 | EC14: 0.0471 | ED14: 0.00304 | EE14: 0.0028 | EF14: 0.000229 | EG14: 0.000557 | EH14: 0.00234 | EI14: 0.286 | EJ14: 0.000255 | EK14: 0.00442 | EL14: 2.21e-05 | EM14: 0.00257 | EN14: 0.0278 | EO14: 2.22e-05 | EP14: 0.000134 | EQ14: 0.000139 | ER14: 0.000304 | ES14: 0.000753 | ET14: 0.11 | EU14: 0.0038 | EV14: 0.00203 | EW14: 5.96e-05 | EX14: 0.000675 | EY14: 0.00136 | EZ14: 3.16e-05 | FA14: 0.00023 | FB14: 0.000634 | FC14: 0.041415285 | FD14: 0.0107684 | FE14: 0.00019578391 | FF14: 0.00020917581 | FG14: 3.3385106e-05 | FH14: 6.96e-05 | FI14: 8.77e-05 | FJ14: 0.000185 | FK14: 1.7e-05 | FL14: 3.16e-06 | FM14: 0.000485 | FN14: 0.00263 | FO14: 0.000172 | FP14: 4.85e-06 | FQ14: 1.8e-05 | FR14: 0.000398 | FS14: 0.0208 | FT14: 0.000101 | FU14: 0.00813 | FV14: 4.86e-05 | FW14: 8.57e-09 | FX14: 0.000161 | FY14: 2.98e-05 | FZ14: 0.000696 | GA14: 6.06e-06 | GB14: 0.000115 | GC14: 9.49e-05 | GD14: 5.64e-06 | GE14: 0.00688 | GF14: 0.00113 | GG14: 3.12e-05 | GH14: 0.000177 | GI14: 9.49e-05 | GJ14: 5.64e-06 | GK14: 0.0078 | GL14: 2.55e-05 | GM14: 0.00598 | GN14: 0.00234 | GO14: 0.000103 | GP14: 0.000192 | GQ14: 0.000432 | GR14: 1.4364004e-05 | GS14: 0.05105854 | GT14: 0.015811462 | GU14: 0.00016942002 | GV14: 9.4309115e-05 | GW14: 4.61e-05 | GX14: 0.000336 | GY14: 0.000208 | GZ14: 3.18e-05 | HA14: 3.16e-06 | HB14: 0.000911 | HC14: 0.0124 | HD14: 0.00012 | HE14: 1.3e-06 | HF14: 2.65e-05 | HG14: 0.000172 | HH14: 0.017 | HI14: 0.00329 | HJ14: 0.000103 | HK14: 6.96e-05 | HL14: 1.59e-05 | HM14: 0.000326 | HN14: 0.000636 | HO14: 5.39e-06 | HP14: 0.000116 | HQ14: 1.38e-05 | HR14: 0.000751 | HS14: 1.06e-05 | HT14: 0.000116 | HU14: 1.51e-05 | HV14: 6.42e-05 | HW14: 0.000116 | HX14: 8.22e-06 | HY14: 0.0256 | HZ14: 0.0572 | IA14: 5.23 | IB14: 114 | IC14: 0.0134 | ID14: =IA14*7 -> 36.61 | IE14: =IB14*7 -> 798 | IF14: =IC14*7 -> 0.0938 | IG14: 0.000323 | IH14: 0.00194 | II14: 0.00645 | IJ14: 0.00104 | IK14: 0.00166 | IL14: -0.0453 | IM14: -0.353 | IN14: -0.905 | IO14: -0.0141 | IP14: 0.000633 | IQ14: -0.0032905464 | IR14: 4.8368242e-05 | IS14: 0.0002916295 | IT14: 0.0046433823 | IU14: 0.00026824799 | IV14: 0.0014824034 | IW14: 0.00253 | IX14: 0.0152 | IY14: 0.00217 | IZ14: 0.00038
