Workbook

Sheet Dashboard Audit
B2: TABLEAU DE BORD — AUDIT FOURNISSEUR / RÉSILIENCE
B5: Société auditée | C5: ='Critères de résilience'!D2 -> RAJA | E5: Fournisseur | F5: ='Critères de résilience'!K2 -> Packaging
B6: Produit | C6: ='Critères de résilience'!R2 -> SDC - VD0993480A Simulation | E6: Date de l'audit
B7: Auditeur / Auditrice
B8: Société auditrice
B11: Famille | C11: Maturité % | D11: Seuil maturité | E11: Criticité /100 | F11: Seuil criticité | G11: Résilience (semaine) | H11: Seuil résilience | I11: Priorité /100
B12: Technique & production | C12: =AVERAGE('Critères de résilience'!F31,'Critères de résilience'!F32,'Critères de résilience'!F33,'Critères de résilience'!F36,'Critères de résilience'!F37,'Critères de résilience'!F38) -> 0.86838384 | D12: 0.75 | E12: =AVERAGE('Critères de résilience'!G31,'Critères de résilience'!G32,'Critères de résilience'!G33,'Critères de résilience'!G36,'Critères de résilience'!G37,'Critères de résilience'!G38) -> 2.3861111 | F12: 15 | G12: =AVERAGE('Critères de résilience'!H31,'Critères de résilience'!H32,'Critères de résilience'!H33,'Critères de résilience'!H36,'Critères de résilience'!H37,'Critères de résilience'!H38) -> 6.5584848 | H12: 70 | I12: =MIN(100,E12*0.4+MIN(G12/30,100)*0.4+(100-C12)*0.2) -> 20.868214
B13: Organisation & données | C13: =AVERAGE('Critères de résilience'!F35,'Critères de résilience'!F39,'Critères de résilience'!F49,'Critères de résilience'!F57) -> 0.69131783 | D13: 0.75 | E13: =AVERAGE('Critères de résilience'!G35,'Critères de résilience'!G39,'Critères de résilience'!G49,'Critères de résilience'!G57) -> 14.183333 | F13: 15 | G13: =AVERAGE('Critères de résilience'!H35,'Critères de résilience'!H39,'Critères de résilience'!H49,'Critères de résilience'!H57) -> 14.383333 | H13: 70 | I13: =MIN(100,E13*0.4+MIN(G13/30,100)*0.4+(100-C13)*0.2) -> 25.726848
B14: RH & sécurité | C14: =AVERAGE('Critères de résilience'!F34,'Critères de résilience'!F40,'Critères de résilience'!F41,'Critères de résilience'!F42,'Critères de résilience'!F43,'Critères de résilience'!F44,'Critères de résilience'!F45,'Critères de résilience'!F46) -> 0.73361111 | D14: 0.75 | E14: =AVERAGE('Critères de résilience'!G34,'Critères de résilience'!G40,'Critères de résilience'!G41,'Critères de résilience'!G42,'Critères de résilience'!G43,'Critères de résilience'!G44,'Critères de résilience'!G45,'Critères de résilience'!G46) -> 3.7270833 | F14: 15 | G14: =AVERAGE('Critères de résilience'!H34,'Critères de résilience'!H40,'Critères de résilience'!H41,'Critères de résilience'!H42,'Critères de résilience'!H43,'Critères de résilience'!H44,'Critères de résilience'!H45,'Critères de résilience'!H46) -> 66.497917 | H14: 70 | I14: =MIN(100,E14*0.4+MIN(G14/30,100)*0.4+(100-C14)*0.2) -> 22.23075
B15: Risques externes | C15: =AVERAGE('Critères de résilience'!F47,'Critères de résilience'!F48,'Critères de résilience'!F58) -> 0.8 | D15: 0.75 | E15: =AVERAGE('Critères de résilience'!G47,'Critères de résilience'!G48,'Critères de résilience'!G58) -> 31.388889 | F15: 15 | G15: =AVERAGE('Critères de résilience'!H47,'Critères de résilience'!H48,'Critères de résilience'!H58) -> 9.4333333 | H15: 70 | I15: =MIN(100,E15*0.4+MIN(G15/30,100)*0.4+(100-C15)*0.2) -> 32.521333
B16: Fournisseurs | C16: =AVERAGE('Critères de résilience'!F52,'Critères de résilience'!F53,'Critères de résilience'!F54,'Critères de résilience'!F55,'Critères de résilience'!F56) -> 0.354 | D16: 0.75 | E16: =AVERAGE('Critères de résilience'!G52,'Critères de résilience'!G53,'Critères de résilience'!G54,'Critères de résilience'!G55,'Critères de résilience'!G56) -> 38.669048 | F16: 15 | G16: =AVERAGE('Critères de résilience'!H52,'Critères de résilience'!H53,'Critères de résilience'!H54,'Critères de résilience'!H55,'Critères de résilience'!H56) -> 110.69286 | H16: 70 | I16: =MIN(100,E16*0.4+MIN(G16/30,100)*0.4+(100-C16)*0.2) -> 36.872724
B17: Activité & marché | C17: =AVERAGE('Critères de résilience'!F51) -> 0.15 | D17: 0.75 | E17: =AVERAGE('Critères de résilience'!G51) -> 30.4 | F17: 15 | G17: =AVERAGE('Critères de résilience'!H51) -> 336.66667 | H17: 70 | I17: =MIN(100,E17*0.4+MIN(G17/30,100)*0.4+(100-C17)*0.2) -> 36.618889
B18: TOTAL / MOYENNE | C18: =AVERAGE(C12:C17) -> 0.59955213 | E18: =AVERAGE(E12:E17) -> 20.125744 | G18: =AVERAGE(G12:G17) -> 90.705432 | I18: =MIN(100,E18*0.4+MIN(G18/30,100)*0.4+(100-C18)*0.2) -> 29.139793
B20: TOILE 1 — MATURITÉ | D20: Niveau de maîtrise actuel du fournisseur.
B21: TOILE 2 — CRITICITÉ | D21: Gravité potentielle des écarts, normalisée sur 100.
B22: TOILE 3 — RÉSILIENCE | D22: Temps nécessaire pour revenir à la conformité.
B23: TOILE 4 — PRIORITÉ D'ACTION | D23: Lecture combinée pour hiérarchiser les actions correctives.

Sheet Essai radar
B2: ='Critères de résilience'!C30 -> 0 | C2: ='Critères de résilience'!F30 -> % maturité | D2: ='Critères de résilience'!G30 -> Criticité | E2: ='Critères de résilience'!H30 -> R (client) en jours | H2: ='Dashboard Audit'!B11 -> Famille | I2: ='Dashboard Audit'!C11 -> Maturité % | J2: ='Dashboard Audit'!E11 -> Criticité /100 | K2: ='Dashboard Audit'!G11 -> Résilience (semaine) | L2: ='Dashboard Audit'!I11 -> Priorité /100
B3: ='Critères de résilience'!C31 -> Propreté des lieux | C3: ='Critères de résilience'!F31 -> 1 | D3: ='Critères de résilience'!G31 -> 1 | E3: ='Critères de résilience'!H31 -> 0 | H3: ='Dashboard Audit'!B12 -> Technique & production | I3: ='Dashboard Audit'!C12 -> 0.86838384 | J3: ='Dashboard Audit'!E12 -> 2.3861111 | K3: ='Dashboard Audit'!G12 -> 6.5584848 | L3: ='Dashboard Audit'!I12 -> 20.868214
B4: ='Critères de résilience'!C32 -> Outillage / Qualité | C4: ='Critères de résilience'!F32 -> 0.96363636 | D4: ='Critères de résilience'!G32 -> 4.1666667 | E4: ='Critères de résilience'!H32 -> 2.46 | H4: ='Dashboard Audit'!B13 -> Organisation & données | I4: ='Dashboard Audit'!C13 -> 0.69131783 | J4: ='Dashboard Audit'!E13 -> 14.183333 | K4: ='Dashboard Audit'!G13 -> 14.383333 | L4: ='Dashboard Audit'!I13 -> 25.726848
B5: ='Critères de résilience'!C33 -> Atelier | C5: ='Critères de résilience'!F33 -> 0.76666667 | D5: ='Critères de résilience'!G33 -> 7 | E5: ='Critères de résilience'!H33 -> 36.090909 | H5: ='Dashboard Audit'!B14 -> RH & sécurité | I5: ='Dashboard Audit'!C14 -> 0.73361111 | J5: ='Dashboard Audit'!E14 -> 3.7270833 | K5: ='Dashboard Audit'!G14 -> 66.497917 | L5: ='Dashboard Audit'!I14 -> 22.23075
B6: ='Critères de résilience'!C34 -> Sûreté | C6: ='Critères de résilience'!F34 -> 0.88888889 | D6: ='Critères de résilience'!G34 -> 3.5 | E6: ='Critères de résilience'!H34 -> 0.25 | H6: ='Dashboard Audit'!B15 -> Risques externes | I6: ='Dashboard Audit'!C15 -> 0.8 | J6: ='Dashboard Audit'!E15 -> 31.388889 | K6: ='Dashboard Audit'!G15 -> 9.4333333 | L6: ='Dashboard Audit'!I15 -> 32.521333
B7: ='Critères de résilience'!C35 -> Conservation des données | C7: ='Critères de résilience'!F35 -> 0.41860465 | D7: ='Critères de résilience'!G35 -> 7.3333333 | E7: ='Critères de résilience'!H35 -> 42.4 | H7: ='Dashboard Audit'!B16 -> Fournisseurs | I7: ='Dashboard Audit'!C16 -> 0.354 | J7: ='Dashboard Audit'!E16 -> 38.669048 | K7: ='Dashboard Audit'!G16 -> 110.69286 | L7: ='Dashboard Audit'!I16 -> 36.872724
B8: ='Critères de résilience'!C36 -> Maintenance | C8: ='Critères de résilience'!F36 -> 1 | D8: ='Critères de résilience'!G36 -> 0 | E8: ='Critères de résilience'!H36 -> 0 | H8: ='Dashboard Audit'!B17 -> Activité & marché | I8: ='Dashboard Audit'!C17 -> 0.15 | J8: ='Dashboard Audit'!E17 -> 30.4 | K8: ='Dashboard Audit'!G17 -> 336.66667 | L8: ='Dashboard Audit'!I17 -> 36.618889
B9: ='Critères de résilience'!C37 -> Formation maintenance | C9: ='Critères de résilience'!F37 -> 0.88 | D9: ='Critères de résilience'!G37 -> 0.4 | E9: ='Critères de résilience'!H37 -> 0.8 | H9: ='Dashboard Audit'!B18 -> TOTAL / MOYENNE | I9: ='Dashboard Audit'!C18 -> 0.59955213 | J9: ='Dashboard Audit'!E18 -> 20.125744 | K9: ='Dashboard Audit'!G18 -> 90.705432 | L9: ='Dashboard Audit'!I18 -> 29.139793
B10: ='Critères de résilience'!C38 -> Disponibilité des pièces détachées pour mes fabrications | C10: ='Critères de résilience'!F38 -> 0.6 | D10: ='Critères de résilience'!G38 -> 1.75 | E10: ='Critères de résilience'!H38 -> 0
B11: ='Critères de résilience'!C39 -> Amélioration continue | C11: ='Critères de résilience'!F39 -> 0.68 | D11: ='Critères de résilience'!G39 -> 14.25 | E11: ='Critères de résilience'!H39 -> 3.1333333
B12: ='Critères de résilience'!C40 -> Formation des salariés | C12: ='Critères de résilience'!F40 -> 0.9 | D12: ='Critères de résilience'!G40 -> 1.1666667 | E12: ='Critères de résilience'!H40 -> 3.1333333
B13: ='Critères de résilience'!C41 -> Connaissance des employés | C13: ='Critères de résilience'!F41 -> 0.88 | D13: ='Critères de résilience'!G41 -> 14.25 | E13: ='Critères de résilience'!H41 -> 3.6
B14: ='Critères de résilience'!C42 -> Turn-over | C14: ='Critères de résilience'!F42 -> 1 | D14: ='Critères de résilience'!G42 -> 1 | E14: ='Critères de résilience'!H42 -> 48
B15: ='Critères de résilience'!C43 -> Accidentologie TG | C15: ='Critères de résilience'!F43 -> 0.5 | D15: ='Critères de résilience'!G43 -> 1.25 | E15: ='Critères de résilience'!H43 -> 45
B16: ='Critères de résilience'!C44 -> Accidentologie TF1 | C16: ='Critères de résilience'!F44 -> 0.5 | D16: ='Critères de résilience'!G44 -> 3.75 | E16: ='Critères de résilience'!H44 -> 270
B17: ='Critères de résilience'!C45 -> Accidentologie TF2 | C17: ='Critères de résilience'!F45 -> 0.2 | D17: ='Critères de résilience'!G45 -> 4.5 | E17: ='Critères de résilience'!H45 -> 162
B18: ='Critères de résilience'!C46 -> Dossier de recherche de cause accident | C18: ='Critères de résilience'!F46 -> 1 | D18: ='Critères de résilience'!G46 -> 0.4 | E18: ='Critères de résilience'!H46 -> 0
B19: ='Critères de résilience'!C47 -> Aléas climatiques | C19: ='Critères de résilience'!F47 -> 0.4 | D19: ='Critères de résilience'!G47 -> 15.333333 | E19: ='Critères de résilience'!H47 -> 28.3
B20: ='Critères de résilience'!C48 -> Aléas industriels | C20: ='Critères de résilience'!F48 -> 1 | D20: ='Critères de résilience'!G48 -> 10 | E20: ='Critères de résilience'!H48 -> 0
B21: ='Critères de résilience'!C49 -> Communication interne | C21: ='Critères de résilience'!F49 -> 0.73333333 | D21: ='Critères de résilience'!G49 -> 2.75 | E21: ='Critères de résilience'!H49 -> 12
... B32: ='Critères de résilience'!C60 -> 0 | C32: ='Critères de résilience'!F60 -> % maturité | D32: ='Critères de résilience'!G60 -> Criticité | E32: ='Critères de résilience'!H60 -> R (client) en semaine

Sheet Mode d'emploi
B2: MODE D'EMPLOI — TRAME D'AUDIT FOURNISSEUR
B5: 1. Saisir les réponses dans « Critères de résilience ».
B6: Les calculs P × I (criticité) et C × TPS (résilience) restent ceux de la trame d'origine.
B7: 2. Le « Dashboard Audit » récupère automatiquement les résultats de la trame.
B8: 3. Les 4 toiles permettent quatre lectures complémentaires : maturité, criticité, résilience et priorité d'action.
B9: 4. Pour un nouvel audit fournisseur, dupliquer le classeur et renseigner société, fournisseur, produit, date et auditeur.
B10: 5. À l'ouverture dans Excel, le recalcul automatique actualise les formules et les graphiques.

Sheet Critères de résilience
C2: Nom de la société: | D2: RAJA | J2: Fournisseur: | K2: Packaging | Q2: Produit | R2: SDC - VD0993480A Simulation
C4: Légende: | D4: Données fournisseur suite audit --> Pts = notation de l'audit sur la question posée TPS (T) = Temps nécessaire pour remise en conformité selon le fournisseur (en jour)
D5: P = probabilité qu'un problème arrive
D6: I = Impact sur la société si un problème survient
D7: C= criticité calculée
D8: R= résilience obtenue pour revenir à situation de conformité (Tps*C)
C10: → Tableau de bord dynamique
C12: Propreté des lieux | D12: Pts | E12: P | F12: I | G12: C= P*I | H12: TPS (T) | I12: R= C*T | J12: Outillage Qualité | K12: Pts | L12: P | M12: I | N12: C= P*I | O12: TPS (T) | P12: R= C*T | Q12: Atelier | R12: Pts | S12: P | T12: I | U12: C= P*I | V12: TPS (T) | W12: R= C*T | X12: Sûreté | Y12: Pts | Z12: P | AA12: I | AB12: C= P*I | AC12: TPS (T) | AD12: R= C*T | AE12: Conservation des données | AF12: 0 | AG12: P | AH12: I | AI12: C= P*I | AJ12: TPS (T) | AK12: R= C*T | AL12: Maintenance | AM12: Pts | AN12: P | AO12: I | AP12: C= P*I | AQ12: TPS (T) | AR12: R= C*T | AS12: Formation Maintenance | AT12: Pts | AU12: P | AV12: I | AW12: C= P*I | AX12: TPS (T) | AY12: R= C*T | AZ12: Disponibilité des pièces détachées pour mes fabrications | BA12: Pts | BB12: P | BC12: I | BD12: C= P*I | BE12: TPS (T) | BF12: R= C*T | BG12: Amélioration continue | BH12: Pts | BI12: P | BJ12: I | BK12: C= P*I | BL12: TPS (T) | BM12: R= C*T | BN12: Formation des salariés | BO12: Pts | BP12: P | BQ12: I | BR12: C= P*I | BS12: TPS (T) | BT12: R= C*T | BU12: Connaissance des employés | BV12: Pts | BW12: P | BX12: I | BY12: C= P*I | BZ12: TPS (T) | CA12: R= C*T | CB12: Turn Over (12 mois glissants) | CC12: Pts | CD12: P | CE12: I | CF12: C= P*I | CG12: TPS (T) | CH12: R= C*T | CI12: Accidentologie TG (12 mois glissants) | CJ12: Pts | CK12: P | CL12: I | CM12: C= P*I | CN12: TPS (T) | CO12: R= C*T | CP12: Accidentologie TF1 (12 mois glissants) | CQ12: Pts | CR12: P | CS12: I | CT12: C= P*I | CU12: TPS (T) | CV12: R= C*T | CW12: Accidentologie TF2 (12 mois glissants) | CX12: Pts | CY12: P | CZ12: I | DA12: C= P*I | DB12: TPS (T) | DC12: R= C*T | DD12: Dossier de recherche de cause suite accident (TG, TF1 et TF2) | DE12: Pts | DF12: P | DG12: I | DH12: C= P*I | DI12: TPS (T) | DJ12: R= C*T | DK12: Aléas climatique | DL12: Pts | DM12: P | DN12: I | DO12: C= P*I | DP12: TPS (T) | DQ12: R= C*T | DR12: Aléas industriel | DS12: Pts | DT12: P | DU12: I | DV12: C= P*I | DW12: TPS (T) | DX12: R= C*T | DY12: Communication interne | DZ12: Pts | EA12: P | EB12: I | EC12: C= P*I | ED12: TPS (T) | EE12: R= C*T | EF12: Risques sociaux | EG12: Pts | EH12: P | EI12: I | EJ12: C= P*I | EK12: TPS (T) | EL12: R= C*T | EM12: Diversification du chiffre d'affaire | EN12: Pts | EO12: P | EP12: I | EQ12: C= P*I | ER12: TPS (T) | ES12: R= C*T | ET12: Diversification des fournisseurs | EU12: Pts | EV12: P | EW12: I | EX12: C= P*I | EY12: TPS (T) | EZ12: R= C*T | FA12: Audits fournisseurs de rang 1 | FB12: Pts | FC12: P | FD12: I | FE12: C= P*I | FF12: TPS (T) | FG12: R= C*T | FH12: Suivi des fournisseurs de rang 1 | FI12: Pts | FJ12: P | FK12: I | FL12: C= P*I | FM12: TPS (T) | FN12: R= C*T | FO12: Identification des fournisseurs de rang 2 | FP12: Pts | FQ12: P | FR12: I | FS12: C= P*I | FT12: TPS (T) | FU12: R= C*T | FV12: Audits fournisseurs de rang 2 | FW12: Pts | FX12: P | FY12: I | FZ12: C= P*I | GA12: TPS (T) | GB12: R= C*T | GC12: Plan de continuité d'activité | GD12: Pts | GE12: P | GF12: I | GG12: C= P*I | GH12: TPS (T) | GI12: R= C*T | GJ12: Transporteur | GK12: Pts | GL12: P | GM12: I | GN12: C= P*I | GO12: TPS (T) | GP12: R= C*T
C13: Les lieux sont globalement propres /5 | D13: 5 | E13: 1 | F13: 1 | G13: =E13*F13 -> 1 | H13: 0 | I13: =H13*G13 -> 0 | J13: Les outils sont rangés, classés et clairement identifiés /5 | K13: 5 | L13: 1 | M13: 2 | N13: =L13*M13 -> 2 | O13: 0 | P13: =O13*N13 -> 0 | Q13: Traçage au sol et signalétique aux murs ou sur panneaux + point de rassemblement /5 | R13: 5 | S13: 1 | T13: 2 | U13: =S13*T13 -> 2 | V13: 45 | W13: =V13*U13 -> 90 | X13: Affichage port de badge obligatoire /5 | Y13: 5 | Z13: 1 | AA13: 2 | AB13: =Z13*AA13 -> 2 | AC13: 0 | AD13: =AC13*AB13 -> 0 | AE13: Sauvegarde Data Center Ins "t" / jour / hebdo / mensuelle /40 | AF13: 0 | AG13: 2 | AH13: 10 | AI13: =AG13*AH13 -> 20 | AJ13: 45 | AK13: =AJ13*AI13 -> 900 | AL13: Calendrier de maintenance préventive interne /5 | AM13: 5 | AN13: 1 | AO13: 0 | AP13: =AN13*AO13 -> 0 | AQ13: 0 | AR13: =AQ13*AP13 -> 0 | AS13: Recyclage permanent des techniciens de maintenance /5 | AT13: 5 | AU13: 1 | AV13: 0 | AW13: =AU13*AV13 -> 0 | AX13: 0 | AY13: =AX13*AW13 -> 0 | AZ13: Pièce ne se fabrique plus et nécessite une entreprise spécialisée pour les refaire /5 | BA13: 0 | BB13: 0 | BC13: 0 | BD13: =BB13*BC13 -> 0 | BE13: 45 | BF13: =BE13*BD13 -> 0 | BG13: Process d'amélioration LEAN en place mesure d'efficacité sur tous les secteurs /10 | BH13: 5 | BI13: 6 | BJ13: 3 | BK13: =BI13*BJ13 -> 18 | BL13: 80 | BM13: =BL13*BK13 -> 1440 | BN13: Oui, au moins 1 formation technique ou 1 remise à niveau par an pour chaque employé /10 | BO13: 9 | BP13: 1 | BQ13: 2 | BR13: =BP13*BQ13 -> 2 | BS13: 45 | BT13: =BS13*BR13 -> 90 | BU13: Ils savent où sont les procédures et savent comment y accéder à tout moment /5 | BV13: 4 | BW13: 1 | BX13: 4 | BY13: =BW13*BX13 -> 4 | BZ13: 20 | CA13: =BZ13*BY13 -> 80 | CB13: Supérieur à 15% /0 | CC13: 0 | CD13: 0 | CE13: 0 | CF13: =CD13*CE13 -> 0 | CG13: 0 | CH13: =CG13*CF13 -> 0 | CI13: entre 0 et 0,5 /10 | CJ13: 0 | CK13: 0 | CL13: 0 | CM13: =CK13*CL13 -> 0 | CN13: 0 | CO13: =CN13*CM13 -> 0 | CP13: entre 0 et 9,99 /10 | CQ13: 0 | CR13: 0 | CS13: 0 | CT13: =CR13*CS13 -> 0 | CU13: 0 | CV13: =CU13*CT13 -> 0 | CW13: entre 0 et 15 /10 | CX13: 0 | CY13: 0 | CZ13: 0 | DA13: =CY13*CZ13 -> 0 | DB13: 0 | DC13: =DB13*DA13 -> 0 | DD13: Oui sur tous /10 | DE13: 10 | DF13: 1 | DG13: 2 | DH13: =DF13*DG13 -> 2 | DI13: 0 | DJ13: =DI13*DH13 -> 0 | DK13: Faille sismique --> Si absence de faille = 10 /10 | DL13: 10 | DM13: 1 | DN13: 10 | DO13: =DM13*DN13 -> 10 | DP13: 0 | DQ13: =DP13*DO13 -> 0 | DR13: Incendie mais formation feu pour tous les salariés /10 | DS13: 10 | DT13: 2 | DU13: 6 | DV13: =DT13*DU13 -> 12 | DW13: 0 | DX13: =DW13*DV13 -> 0 | DY13: Affichage bilan social et syndical de l'entreprise /5 | DZ13: 5 | EA13: 1 | EB13: 1 | EC13: =EA13*EB13 -> 1 | ED13: 0 | EE13: =ED13*EC13 -> 0 | EF13: Aucuns mouvements sociaux depuis plus de 5 ans --> Si ok = 20 pour toute la colonne /20 | EG13: 20 | EH13: 0 | EI13: 0 | EJ13: =EH13*EI13 -> 0 | EK13: 0 | EL13: =EK13*EJ13 -> 0 | EM13: L'activité est pluri-sectorielle /10 | EN13: 0 | EO13: 2 | EP13: 8 | EQ13: =EO13*EP13 -> 16 | ER13: 50 | ES13: =ER13*EQ13 -> 800 | ET13: Les fournisseurs sont systématiquement triplés et chacuns sont dûment certifiés /30 | EU13: 0 | EV13: 1 | EW13: 5 | EX13: =EV13*EW13 -> 5 | EY13: 1 | EZ13: =EY13*EX13 -> 5 | FA13: Audits systématiques selon un plan et une planification d'audit annuel 10 | FB13: 10 | FC13: 10 | FD13: 10 | FE13: =FC13*FD13 -> 100 | FF13: 0 | FG13: =FF13*FE13 -> 0 | FH13: Seuil qualité ou délais stipulés sur les contrats d'achats /10 | FI13: 8 | FJ13: 2 | FK13: 9 | FL13: =FJ13*FK13 -> 18 | FM13: 10 | FN13: =FM13*FL13 -> 180 | FO13: Indentification de tous les rangs 2 /10 | FP13: 0 | FQ13: 0 | FR13: 0 | FS13: =FQ13*FR13 -> 0 | FT13: 0 | FU13: =FT13*FS13 -> 0 | FV13: Audits systématiques suite à incidents des rangs 2 /20 | FW13: 0 | FX13: 0 | FY13: 0 | FZ13: =FX13*FY13 -> 0 | GA13: 0 | GB13: =GA13*FZ13 -> 0 | GC13: En place et complet (si quelques oublis --> note entre 11 et 14) /15 | GD13: 14 | GE13: 2 | GF13: 1 | GG13: =GE13*GF13 -> 2 | GH13: 0 | GI13: =GH13*GG13 -> 0 | GJ13: Interne et plusieurs prestataires réguliers route rail bateau /30 | GK13: 30 | GL13: 15 | GM13: 10 | GN13: =GL13*GM13 -> 150 | GO13: 0 | GP13: =GO13*GN13 -> 0
C14: Les sanitaires et réfectoire sont propres /5 | D14: 5 | E14: 1 | F14: 1 | G14: =E14*F14 -> 1 | H14: 0 | I14: =H14*G14 -> 0 | J14: Aucuns outils sont défectueux /5 | K14: 5 | L14: 1 | M14: 10 | N14: =L14*M14 -> 10 | O14: 0 | P14: =O14*N14 -> 0 | Q14: Protocole chargement / dechargement en place /5 | R14: 5 | S14: 1 | T14: 3 | U14: =S14*T14 -> 3 | V14: 45 | W14: =V14*U14 -> 135 | X14: Détention de carte professionnelle des gardiens /5 | Y14: 5 | Z14: 1 | AA14: 1 | AB14: =Z14*AA14 -> 1 | AC14: 0 | AD14: =AC14*AB14 -> 0 | AE14: Sauvegarde DD interne Ins "t" / jour / hebdo / mensuelle /20 | AF14: 15 | AG14: 2 | AH14: 4 | AI14: =AG14*AH14 -> 8 | AJ14: 45 | AK14: =AJ14*AI14 -> 360 | AL14: Maintenance corrective interne /5 | AM14: 5 | AN14: 1 | AO14: 0 | AP14: =AN14*AO14 -> 0 | AQ14: 0 | AR14: =AQ14*AP14 -> 0 | AS14: Présence de technicien de ligne /5 | AT14: 5 | AU14: 1 | AV14: 0 | AW14: =AU14*AV14 -> 0 | AX14: 0 | AY14: =AX14*AW14 -> 0 | AZ14: Pièces les moins courantes disponibles sous 2 semaines /5 | BA14: 0 | BB14: 0 | BC14: 0 | BD14: =BB14*BC14 -> 0 | BE14: 45 | BF14: =BE14*BD14 -> 0 | BG14: Process d'amélioration LEAN en place et mesure d'efficacité non totalement déployé sur tous les secteurs /10 | BH14: 7 | BI14: 5 | BJ14: 3 | BK14: =BI14*BJ14 -> 15 | BL14: 60 | BM14: =BL14*BK14 -> 900 | BN14: Formation faite au cas par cas en fonction du besoin /10 | BO14: 10 | BP14: 1 | BQ14: 1 | BR14: =BP14*BQ14 -> 1 | BS14: 0 | BT14: =BS14*BR14 -> 0 | BU14: Ils ont été porté à connaissance de l'evolution de chaque procédure leurs étant associés (signature) /5 | BV14: 5 | BW14: 1 | BX14: 4 | BY14: =BW14*BX14 -> 4 | BZ14: 0 | CA14: =BZ14*BY14 -> 0 | CB14: Entre 10 et 14,99 % /2 | CC14: 0 | CD14: 0 | CE14: 0 | CF14: =CD14*CE14 -> 0 | CG14: 0 | CH14: =CG14*CF14 -> 0 | CI14: entre 0,51 et 1 /5 | CJ14: 5 | CK14: 1 | CL14: 5 | CM14: =CK14*CL14 -> 5 | CN14: 180 | CO14: =CN14*CM14 -> 900 | CP14: entre 10 et 14,99 /5 | CQ14: 5 | CR14: 5 | CS14: 3 | CT14: =CR14*CS14 -> 15 | CU14: 360 | CV14: =CU14*CT14 -> 5400 | CW14: entre 15,01 et 30 /5 | CX14: 0 | CY14: 0 | CZ14: 0 | DA14: =CY14*CZ14 -> 0 | DB14: 0 | DC14: =DB14*DA14 -> 0 | DD14: Oui uniquement si TG et TF1 impactés /5 | DE14: 0 | DF14: 0 | DG14: 0 | DH14: =DF14*DG14 -> 0 | DI14: 0 | DJ14: =DI14*DH14 -> 0 | DK14: Inondation risque élevé (cours d'eau, flanc de montagne ou dans une vallée étroite) Si absence de risque = 10 /10 | DL14: 4 | DM14: 5 | DN14: 10 | DO14: =DM14*DN14 -> 50 | DP14: 15 | DQ14: =DP14*DO14 -> 750 | DR14: Sprinkler et bassin d'alimentation en eau en place - inspection régulière /10 | DS14: 10 | DT14: 2 | DU14: 6 | DV14: =DT14*DU14 -> 12 | DW14: 0 | DX14: =DW14*DV14 -> 0 | DY14: Capacité des salariés à exprimer leurs souhaits / mecontentements /10 | DZ14: 7 | EA14: 2 | EB14: 1 | EC14: =EA14*EB14 -> 2 | ED14: 30 | EE14: =ED14*EC14 -> 60 | EF14: Aucuns mouvements sociaux depuis plus de 3 ans --> Si ok = 15 pour toute la colonne /15 | EG14: 0 | EH14: 4 | EI14: 2 | EJ14: =EH14*EI14 -> 8 | EK14: 0 | EL14: =EK14*EJ14 -> 0 | EM14: L'activité est bi-sectorielle /5 | EN14: 0 | EO14: 2 | EP14: 8 | EQ14: =EO14*EP14 -> 16 | ER14: 50 | ES14: =ER14*EQ14 -> 800 | ET14: Il n'y a que deux fournisseurs pour chaque typologie de pièce /20 | EU14: 0 | EV14: 4 | EW14: 7 | EX14: =EV14*EW14 -> 28 | EY14: 50 | EZ14: =EY14*EX14 -> 1400 | FA14: Audits suite à dégradation de service sans pour autant qu'il soit hors tolérance en contrôle d'entrée /10 | FB14: 7 | FC14: 10 | FD14: 10 | FE14: =FC14*FD14 -> 100 | FF14: 15 | FG14: =FF14*FE14 -> 1500 | FH14: Fichier de suivi fournisseurs (performance, délai consignés) /10 | FI14: 10 | FJ14: 5 | FK14: 5 | FL14: =FJ14*FK14 -> 25 | FM14: 0 | FN14: =FM14*FL14 -> 0 | FO14: Identification des rangs 2 uniquement sur les fournisseurs rang 1 critiques /5 | FP14: 0 | FQ14: 0 | FR14: 0 | FS14: =FQ14*FR14 -> 0 | FT14: 0 | FU14: =FT14*FS14 -> 0 | FV14: Suivi administratif des certifications et habilitations fournisseur rang 2 /20 | FW14: 0 | FX14: 0 | FY14: 0 | FZ14: =FX14*FY14 -> 0 | GA14: 0 | GB14: =GA14*FZ14 -> 0 | GC14: En place et complet mais inconnu du personnel /10 | GD14: 0 | GE14: 2 | GF14: 10 | GG14: =GE14*GF14 -> 20 | GH14: 0 | GI14: =GH14*GG14 -> 0 | GJ14: Plusieurs prestataires route-rail-bateau /20 | GK14: 0 | GL14: 3 | GM14: 1 | GN14: =GL14*GM14 -> 3 | GO14: 0 | GP14: =GO14*GN14 -> 0
C15: L'atelier est clairement sectorisé /5 | D15: 5 | E15: 1 | F15: 1 | G15: =E15*F15 -> 1 | H15: 0 | I15: =H15*G15 -> 0 | J15: Suivi d'étalonnage rigoureux /5 | K15: 5 | L15: 1 | M15: 10 | N15: =L15*M15 -> 10 | O15: 0 | P15: =O15*N15 -> 0 | Q15: Plan de circulation externe affiché de manière clair et visible par les routiers et les visiteurs /5 | R15: 2 | S15: 5 | T15: 3 | U15: =S15*T15 -> 15 | V15: 10 | W15: =V15*U15 -> 150 | X15: Signature et suivi des rondes de garde à jour /5 | Y15: 5 | Z15: 1 | AA15: 1 | AB15: =Z15*AA15 -> 1 | AC15: 0 | AD15: =AC15*AB15 -> 0 | AE15: Archive papier externe annuelle /9 | AF15: 9 | AG15: 4 | AH15: 1 | AI15: =AG15*AH15 -> 4 | AJ15: 0 | AK15: =AJ15*AI15 -> 0 | AL15: Calendrier de maintenance préventive externe /5 | AM15: 5 | AN15: 1 | AO15: 0 | AP15: =AN15*AO15 -> 0 | AQ15: 0 | AR15: =AQ15*AP15 -> 0 | AS15: Recyclage des techniciens de ligne /5 | AT15: 5 | AU15: 1 | AV15: 0 | AW15: =AU15*AV15 -> 0 | AX15: 0 | AY15: =AX15*AW15 -> 0 | AZ15: Pièces les moins courantes disponibles sous 1 semaine (1pt/j) /5 | BA15: 5 | BB15: 1 | BC15: 2 | BD15: =BB15*BC15 -> 2 | BE15: 0 | BF15: =BE15*BD15 -> 0 | BG15: Process d'amélioration Lean en cours de mise en place /5 | BH15: 5 | BI15: 6 | BJ15: 4 | BK15: =BI15*BJ15 -> 24 | BL15: 0 | BM15: =BL15*BK15 -> 0 | BN15: Plan de formation existant /10 | BO15: 10 | BP15: 0 | BQ15: 0 | BR15: =BP15*BQ15 -> 0 | BS15: 0 | BT15: =BS15*BR15 -> 0 | BU15: Ils ont le reflexe d'identifier le besoin et d'aller voir leur manager pour obtenir les procédures associées /5 | BV15: 3 | BW15: 1 | BX15: 1 | BY15: =BW15*BX15 -> 1 | BZ15: 10 | CA15: =BZ15*BY15 -> 10 | CB15: Entre 5 et 9,99% /10 | CC15: 10 | CD15: 2 | CE15: 2 | CF15: =CD15*CE15 -> 4 | CG15: 60 | CH15: =CG15*CF15 -> 240 | CI15: entre 1 et 1,99 /2 | CJ15: 0 | CK15: 0 | CL15: 0 | CM15: =CK15*CL15 -> 0 | CN15: 0 | CO15: =CN15*CM15 -> 0 | CP15: entre 15 et 20 /2 | CQ15: 0 | CR15: 0 | CS15: 0 | CT15: =CR15*CS15 -> 0 | CU15: 0 | CV15: =CU15*CT15 -> 0 | CW15: entre 30,01 et 45 /2 | CX15: 2 | CY15: 6 | CZ15: 3 | DA15: =CY15*CZ15 -> 18 | DB15: 180 | DC15: =DB15*DA15 -> 3240 | DD15: Oui uniquement si TG impacté /2 | DE15: 0 | DF15: 0 | DG15: 0 | DH15: =DF15*DG15 -> 0 | DI15: 0 | DJ15: =DI15*DH15 -> 0 | DK15: Vent (fréquent et violent) Si absence de risque = 10 /10 | DL15: 4 | DM15: 3 | DN15: 3 | DO15: =DM15*DN15 -> 9 | DP15: 6 | DQ15: =DP15*DO15 -> 54 | DR15: Système d'extinction automatique des incendies /10 | DS15: 10 | DT15: 2 | DU15: 8 | DV15: =DT15*DU15 -> 16 | DW15: 0 | DX15: =DW15*DV15 -> 0 | DY15: Accessibilité du management /10 | DZ15: 5 | EA15: 2 | EB15: 2 | EC15: =EA15*EB15 -> 4 | ED15: 45 | EE15: =ED15*EC15 -> 180 | EF15: Plan social en cours --> Si oui = 0 pour toute la colonne | EG15: 0 | EH15: 0 | EI15: 0 | EJ15: =EH15*EI15 -> 0 | EK15: 0 | EL15: =EK15*EJ15 -> 0 | EM15: L'activité est mono sectorielle /1 | EN15: 1 | EO15: 2 | EP15: 10 | EQ15: =EO15*EP15 -> 20 | ER15: 50 | ES15: =ER15*EQ15 -> 1000 | ET15: Il n'y a souvent que 1 ou 2 fournisseurs potentiels pour chaque typologie de pièce /15 | EU15: 0 | EV15: 6 | EW15: 8 | EX15: =EV15*EW15 -> 48 | EY15: 50 | EZ15: =EY15*EX15 -> 2400 | FA15: Audits systématiques suite à incidents /10 | FB15: 10 | FC15: 10 | FD15: 10 | FE15: =FC15*FD15 -> 100 | FF15: 0 | FG15: =FF15*FE15 -> 0 | FH15: Mise sous surveillance en cas de niveau qualité inférieur au taux maximal autorisé sur contrat d'achat /10 | FI15: 10 | FJ15: 1 | FK15: 5 | FL15: =FJ15*FK15 -> 5 | FM15: 0 | FN15: =FM15*FL15 -> 0 | FO15: Aucune identification des rangs 2 --> 0 sur tous les critères sauf cette ligne au maxi en P et I | FP15: 0 | FQ15: 10 | FR15: 10 | FS15: =FQ15*FR15 -> 100 | FT15: 50 | FU15: =FT15*FS15 -> 5000 | FV15: Audits systématiques suite à incidents uniquement sur les fournisseurs rang 3 critiques /10 | FW15: 0 | FX15: 0 | FY15: 0 | FZ15: =FX15*FY15 -> 0 | GA15: 0 | GB15: =GA15*FZ15 -> 0 | GC15: Non abouti ou partiel mais connu du personnel /5 | GD15: 0 | GE15: 4 | GF15: 10 | GG15: =GE15*GF15 -> 40 | GH15: 0 | GI15: =GH15*GG15 -> 0 | GJ15: Unique prestataire route /15 | GK15: 0 | GL15: 10 | GM15: 10 | GN15: =GL15*GM15 -> 100 | GO15: 0 | GP15: =GO15*GN15 -> 0
C16: Les postes de travails sont propres et ordonnés /5 | D16: 5 | E16: 1 | F16: 1 | G16: =E16*F16 -> 1 | H16: 0 | I16: =H16*G16 -> 0 | J16: Contrôle qualité en amont de la fabrication /5 | K16: 5 | L16: 1 | M16: 1 | N16: =L16*M16 -> 1 | O16: 0 | P16: =O16*N16 -> 0 | Q16: Plan de circulation interne affiché de manière clair et visible par les routiers et les visiteurs /5 | R16: 2 | S16: 5 | T16: 3 | U16: =S16*T16 -> 15 | V16: 4 | W16: =V16*U16 -> 60 | X16: Bordereau de vérification périodique de l'état des clôtures 5 | Y16: 5 | Z16: 2 | AA16: 1 | AB16: =Z16*AA16 -> 2 | AC16: 0 | AD16: =AC16*AB16 -> 0 | AE16: Archive papier interne jour / hebdo / mensuelle /5 | AF16: 5 | AG16: 4 | AH16: 1 | AI16: =AG16*AH16 -> 4 | AJ16: 0 | AK16: =AJ16*AI16 -> 0 | AL16: Contrat de maintenance externe sur machines sensibles /5 | AM16: 5 | AN16: 1 | AO16: 0 | AP16: =AN16*AO16 -> 0 | AQ16: 0 | AR16: =AQ16*AP16 -> 0 | AS16: Habilitation électrique mini H1B1 pour les techniciens de maintenance /5 | AT16: 5 | AU16: 1 | AV16: 0 | AW16: =AU16*AV16 -> 0 | AX16: 0 | AY16: =AX16*AW16 -> 0 | AZ16: Stock de pièce détachées capable de répondre à 95% des pannes /10 | BA16: 10 | BB16: 5 | BC16: 1 | BD16: =BB16*BC16 -> 5 | BE16: 0 | BF16: =BE16*BD16 -> 0 | BG16: Process d'amélioration Lean non déployé /5 | BH16: 0 | BI16: 0 | BJ16: 0 | BK16: =BI16*BJ16 -> 0 | BL16: 0 | BM16: =BL16*BK16 -> 0 | BN16: Tableau de polyvalence existe et est clairement affiché sur chaque poste de travail /10 | BO16: 6 | BP16: 2 | BQ16: 1 | BR16: =BP16*BQ16 -> 2 | BS16: 1 | BT16: =BS16*BR16 -> 2 | BU16: Ils savent ou trouver le document unique en cas de besoin /5 | BV16: 5 | BW16: 1 | BX16: 1 | BY16: =BW16*BX16 -> 1 | BZ16: 0 | CA16: =BZ16*BY16 -> 0 | CB16: Inférieur à 5% /5 | CC16: 0 | CD16: 0 | CE16: 0 | CF16: =CD16*CE16 -> 0 | CG16: 0 | CH16: =CG16*CF16 -> 0 | CI16: Supérieur à 2 /0 | CJ16: 0 | CK16: 0 | CL16: 0 | CM16: =CK16*CL16 -> 0 | CN16: 0 | CO16: =CN16*CM16 -> 0 | CP16: Supérieur à 20 /0 | CQ16: 0 | CR16: 0 | CS16: 0 | CT16: =CR16*CS16 -> 0 | CU16: 0 | CV16: =CU16*CT16 -> 0 | CW16: Supérieur à 45,01 | CX16: 0 | CY16: 0 | CZ16: 0 | DA16: =CY16*CZ16 -> 0 | DB16: 0 | DC16: =DB16*DA16 -> 0 | DD16: Pas systématiquement, 1 ou des oublis sont détectés /2 | DE16: 0 | DF16: 0 | DG16: 0 | DH16: =DF16*DG16 -> 0 | DI16: 0 | DJ16: =DI16*DH16 -> 0 | DK16: Neige Si absence de risque = 10 /10 | DL16: 1 | DM16: 1 | DN16: 2 | DO16: =DM16*DN16 -> 2 | DP16: 1 | DQ16: =DP16*DO16 -> 2 | DR16: Risque Seveso à proximité Si absence de risque = 10 /10 | DS16: 10 | DT16: 0 | DU16: 0 | DV16: =DT16*DU16 -> 0 | DW16: 0 | DX16: =DW16*DV16 -> 0 | DY16: Affichages réglementaire en place /5 | DZ16: 5 | EA16: 2 | EB16: 2 | EC16: =EA16*EB16 -> 4 | ED16: 0 | EE16: =ED16*EC16 -> 0 | EF16: Plan social avant les 3 dernières années --> Si oui = 5 pour toute la colonne | EG16: 0 | EH16: 0 | EI16: 0 | EJ16: =EH16*EI16 -> 0 | EK16: 0 | EL16: =EK16*EJ16 -> 0 | EM16: Les clients sont diversifiés, aucun ne représente plus de 20% du CA /10 | EN16: 0 | EO16: 5 | EP16: 8 | EQ16: 50 | ER16: 50 | ES16: =ER16*EQ16 -> 2500 | ET16: Il n'y a qu'un fournisseur pour chaque typologie de pièce /5 | EU16: 5 | EV16: 10 | EW16: 10 | EX16: =EV16*EW16 -> 100 | EY16: 0 | EZ16: =EY16*EX16 -> 0 | FA16: Audit uniquement à la première commande --> Si ok = 0 pour les 4 premières ligne pour toute la colonne /5 | FB16: 5 | FC16: 10 | FD16: 10 | FE16: =FC16*FD16 -> 100 | FF16: 0 | FG16: =FF16*FE16 -> 0 | FH16: Suivi administratif des certifications et habilitations fournisseur /10 | FI16: 10 | FJ16: 1 | FK16: 1 | FL16: =FJ16*FK16 -> 1 | FM16: 0 | FN16: =FM16*FL16 -> 0 | FO16: Suivi capacitaire de tous les rangs 2 /10 | FP16: 0 | FQ16: 0 | FR16: 0 | FS16: =FQ16*FR16 -> 0 | FT16: 0 | FU16: =FT16*FS16 -> 0 | FV16: Suivi administratif des certifications et habilitations uniquement sur les fournisseurs rang 3 critiques /10 | FW16: 0 | FX16: 10 | FY16: 0 | FZ16: 50 | GA16: 0 | GB16: =GA16*FZ16 -> 0 | GC16: Non abouti ou partiel (Ex: uniquement en cas d'absence de management) /2 | GD16: 0 | GE16: 2 | GF16: 10 | GG16: =GE16*GF16 -> 20 | GH16: 0 | GI16: =GH16*GG16 -> 0 | GJ16: En interne tous transports confondus /10 | GK16: 0 | GL16: 5 | GM16: 10 | GN16: =GL16*GM16 -> 50 | GO16: 0 | GP16: =GO16*GN16 -> 0
C17: Les performances du site sont clairement affichées /5 | D17: 5 | E17: 1 | F17: 1 | G17: =E17*F17 -> 1 | H17: 0 | I17: =H17*G17 -> 0 | J17: Contrôle qualité en milieu de fabrication /5 | K17: 5 | L17: 1 | M17: 1 | N17: =L17*M17 -> 1 | O17: 0 | P17: =O17*N17 -> 0 | Q17: Les objectifs qualité, sécurité et productivité sont clairement affichés sur chaque poste de travail et par unité /5 | R17: 4 | S17: 1 | T17: 1 | U17: =S17*T17 -> 1 | V17: 2 | W17: =V17*U17 -> 2 | X17: Présence de gardien de nuit /5 | Y17: 5 | Z17: 2 | AA17: 5 | AB17: =Z17*AA17 -> 10 | AC17: 0 | AD17: =AC17*AB17 -> 0 | AE17: Archive papier interne annuelle /2 | AF17: 2 | AG17: 4 | AH17: 1 | AI17: =AG17*AH17 -> 4 | AJ17: 0 | AK17: =AJ17*AI17 -> 0 | AL17: Contrat de maintenance externe sur toutes machines /5 | AM17: 5 | AN17: 1 | AO17: 0 | AP17: =AN17*AO17 -> 0 | AQ17: 0 | AR17: =AQ17*AP17 -> 0 | AS17: Minimum 1 technicien H2B2-HRBR par équipe /5 | AT17: 2 | AU17: 1 | AV17: 2 | AW17: =AU17*AV17 -> 2 | AX17: 10 | AY17: =AX17*AW17 -> 20 | BN17: Les matières dangereuses sont clairement identifiées /5 | BO17: 5 | BP17: 1 | BQ17: 1 | BR17: =BP17*BQ17 -> 1 | BS17: 2 | BT17: =BS17*BR17 -> 2 | BU17: Ils savent ou se trouve les affichages réglementaires de l'entreprise /5 | BV17: 5 | BW17: 1 | BX17: 1 | BY17: =BW17*BX17 -> 1 | BZ17: 0 | CA17: =BZ17*BY17 -> 0 | DD17: Non /0 | DE17: 0 | DF17: 0 | DG17: 0 | DH17: =DF17*DG17 -> 0 | DI17: 0 | DJ17: =DI17*DH17 -> 0 | DK17: Tornade / cyclonique Si absence de risque = 10 /10 | DL17: 4 | DM17: 4 | DN17: 5 | DO17: =DM17*DN17 -> 20 | DP17: 2 | DQ17: =DP17*DO17 -> 40 | EF17: Rachat de l'entreprise avant les 3 dernière années --> Si oui = 5 pour toute la colonne | EG17: 0 | EH17: 0 | EI17: 0 | EJ17: =EH17*EI17 -> 0 | EK17: 0 | EL17: =EK17*EJ17 -> 0 | EM17: 1 client représente plus de 20% du chiffre d'affaire /5 | EN17: 1 | EO17: 5 | EP17: 8 | EQ17: 50 | ER17: 50 | ES17: =ER17*EQ17 -> 2500 | FA17: Suivi des rapports d'audits ET du plan d'amélioration fournisseur /10 | FB17: 10 | FC17: 10 | FD17: 10 | FE17: =FC17*FD17 -> 100 | FF17: 0 | FG17: =FF17*FE17 -> 0 | FH17: Respect des délais /10 | FI17: 5 | FJ17: 5 | FK17: 5 | FL17: =FJ17*FK17 -> 25 | FM17: 6 | FN17: =FM17*FL17 -> 150 | FO17: Suivi capacitaire des rangs 2 uniquement sur les fournisseurs rang 1 critiques /5 | FP17: 0 | FQ17: 0 | FR17: 0 | FS17: =FQ17*FR17 -> 0 | FT17: 0 | FU17: =FT17*FS17 -> 0 | FV17: Demande de rapports réguliers sur les performances qualités des fournisseurs de rang 3 aux fournisseurs de rang 2 /10 | FW17: 0 | FX17: 0 | FY17: 0 | FZ17: =FX17*FY17 -> 0 | GA17: 0 | GB17: =GA17*FZ17 -> 0 | GC17: Absence de PCA --> 0 pour toute la colonne | GD17: 0 | GE17: 8 | GF17: 10 | GG17: =GE17*GF17 -> 80 | GH17: 0 | GI17: =GH17*GG17 -> 0 | GJ17: En interne + back-up en cas de besoin /20 | GK17: 20 | GL17: 2 | GM17: 5 | GN17: =GL17*GM17 -> 10 | GO17: 0 | GP17: =GO17*GN17 -> 0
C18: Les performances sécurité du site sont clairement affichées /5 | D18: 5 | E18: 1 | F18: 1 | G18: =E18*F18 -> 1 | H18: 0 | I18: =H18*G18 -> 0 | J18: Contrôle qualité en fin de fabrication /10 | K18: 5 | L18: 1 | M18: 1 | N18: =L18*M18 -> 1 | O18: 3 | P18: =O18*N18 -> 3 | Q18: Les ÉPI obligatoire et recommandés sont portés systématiquement. /5 | R18: 4 | S18: 2 | T18: 3 | U18: =S18*T18 -> 6 | V18: 3 | W18: =V18*U18 -> 18 | X18: Local informatique propre et ventilé /5 | Y18: 5 | Z18: 1 | AA18: 5 | AB18: =Z18*AA18 -> 5 | AC18: 0 | AD18: =AC18*AB18 -> 0 | AE18: Durée d'archivage (entre 6 et10 ans) /10 | AF18: 5 | AG18: 4 | AH18: 1 | AI18: =AG18*AH18 -> 4 | AJ18: 3 | AK18: =AJ18*AI18 -> 12 | AL18: Technicien de maintenance 1er niveau dédié sur ligne /5 | AM18: 5 | AN18: 1 | AO18: 0 | AP18: =AN18*AO18 -> 0 | AQ18: 0 | AR18: =AQ18*AP18 -> 0 | BN18: Un référent matière dangereuse est nommé et clairement connu /5 | BO18: 5 | BP18: 1 | BQ18: 1 | BR18: =BP18*BQ18 -> 1 | BS18: 0 | BT18: =BS18*BR18 -> 0 | DK18: Risque de feu de forêt Si absence de risque = 10 /10 | DL18: 1 | DM18: 1 | DN18: 1 | DO18: =DM18*DN18 -> 1 | DP18: 3 | DQ18: =DP18*DO18 -> 3 | EF18: Rachat de l'entreprise avant les 3 dernières années + PSE --> Si oui = 2 pour toute la colonne | EG18: 0 | EH18: 0 | EI18: 0 | EJ18: =EH18*EI18 -> 0 | EK18: 0 | EL18: =EK18*EJ18 -> 0 | EM18: 1 client représente plus de 30% du chiffre d'affaire /1 | EN18: 1 | EO18: 5 | EP18: 8 | EQ18: 50 | ER18: 50 | ES18: =ER18*EQ18 -> 2500 | FA18: Pas d'audits fournisseurs systématique = 0 pour toute la colonne | FB18: 0 | FC18: 10 | FD18: 5 | FE18: =FC18*FD18 -> 50 | FF18: 0 | FG18: =FF18*FE18 -> 0 | FH18: Respect des seuils qualités /10 | FI18: 4 | FJ18: 4 | FK18: 4 | FL18: =FJ18*FK18 -> 16 | FM18: 2 | FN18: =FM18*FL18 -> 32 | FV18: Pas de suivi rang 2 = 0 sur tous les critères sauf cette ligne au maxi en P et I | FW18: 0 | FX18: 10 | FY18: 10 | FZ18: =FX18*FY18 -> 100 | GA18: 60 | GB18: =GA18*FZ18 -> 6000 | GJ18: Unique prestataire route-bateau- rail /5 | GK18: 0 | GL18: 10 | GM18: 10 | GN18: =GL18*GM18 -> 100 | GO18: 0 | GP18: =GO18*GN18 -> 0
C19: Les bureaux sont bien rangés /5 | D19: 5 | E19: 1 | F19: 1 | G19: =E19*F19 -> 1 | H19: 0 | I19: =H19*G19 -> 0 | J19: Tracabilité des contrôles qualité /10 | K19: 10 | L19: 1 | M19: 10 | N19: =L19*M19 -> 10 | O19: 0 | P19: =O19*N19 -> 0 | Q19: Les critères des audits 5S sont continuellement revus afin de maintenir l’amélioration de la sécurité. /5 | R19: 4 | S19: 1 | T19: 2 | U19: =S19*T19 -> 2 | V19: 15 | W19: =V19*U19 -> 30 | X19: Système de surveillance extérieur par caméra /10 | Y19: 5 | Z19: 1 | AA19: 1 | AB19: =Z19*AA19 -> 1 | AC19: 10 | AD19: =AC19*AB19 -> 10 | FA19: Pas d'audit fournisseurs =0 pour toute la colonne | FB19: 0 | FC19: 10 | FD19: 5 | FE19: =FC19*FD19 -> 50 | FF19: 0 | FG19: =FF19*FE19 -> 0 | FH19: Adaptabilité des délais /10 | FI19: 5 | FJ19: 4 | FK19: 6 | FL19: =FJ19*FK19 -> 24 | FM19: 2 | FN19: =FM19*FL19 -> 48 | FV19: Pas d'audits fournisseurs rang 2 systématiques = 2 sur toute la colonne | FW19: 0 | FX19: 0 | FY19: 0 | FZ19: =FX19*FY19 -> 0 | GA19: 0 | GB19: =GA19*FZ19 -> 0
C20: Les extérieurs sont entretenus /5 | D20: 5 | E20: 1 | F20: 1 | G20: =E20*F20 -> 1 | H20: 0 | I20: =H20*G20 -> 0 | J20: Formation continue des qualiticiens /10 | K20: 8 | L20: 4 | M20: 3 | N20: =L20*M20 -> 12 | O20: 10 | P20: =O20*N20 -> 120 | Q20: Le système de management HSE est utilisé comme un moyen d’amélioration continue. Le système est actuel et opérationnel et fait l’objet de discussions régulières lors des revues de direction mensuelles /5 | R20: 5 | S20: 1 | T20: 1 | U20: =S20*T20 -> 1 | V20: 0 | W20: =V20*U20 -> 0 | X20: Système de surveillance extérieur par caméra ET contrôle externalisé /5 | Y20: 5 | Z20: 1 | AA20: 1 | AB20: =Z20*AA20 -> 1 | AC20: 0 | AD20: =AC20*AB20 -> 0 | FA20: Audits systématiques suite à incidents uniquement sur les fournisseurs rang 2 critiques /10 | FB20: 10 | FC20: 10 | FD20: 10 | FE20: =FC20*FD20 -> 100 | FF20: 0 | FG20: =FF20*FE20 -> 0 | FV20: Respect des délais /10 | FW20: 0 | FX20: 0 | FY20: 0 | FZ20: =FX20*FY20 -> 0 | GA20: 0 | GB20: =GA20*FZ20 -> 0
J21: Obtention EN9100 /5 | K21: NA | L21: 0 | M21: 0 | N21: =L21*M21 -> 0 | O21: 0 | P21: =O21*N21 -> 0 | Q21: Il y a un recours supplémentaire de l’équipe ingéniérie et technique qui consacre 1/4 d’équivalent temps plein pour une entité avec 250 P, aux questions de sécurité. Exemples : Ergonomie, sécurité des machines, sécurité Kaizen… Le responsable Sécurité et Environnement relève directement du responsable du site. /5 | R21: 0 | S21: 4 | T21: 6 | U21: =S21*T21 -> 24 | V21: 60 | W21: =V21*U21 -> 1440 | FA21: Suivi administratif des certifications et habilitations uniquement sur les fournisseurs rang 2 critiques /10 | FB21: 10 | FC21: 10 | FD21: 10 | FE21: =FC21*FD21 -> 100 | FF21: 0 | FG21: =FF21*FE21 -> 0 | FV21: Respect des seuils qualités /10 | FW21: 0 | FX21: 0 | FY21: 0 | FZ21: =FX21*FY21 -> 0 | GA21: 0 | GB21: =GA21*FZ21 -> 0
J22: Obtention ISO 9000 /5 | K22: 5 | L22: 1 | M22: 1 | N22: =L22*M22 -> 1 | O22: 0 | P22: =O22*N22 -> 0 | Q22: Une fiche de données de sécurité (FDS) doit être facilement accessible à tous les employés pour tout produit chimique utilisé. Tous les produits chimiques sont dans des contenants correctement étiquetés. Les étiquettes appropriées doivent inclure le nom chimique (traçable à une FDS) et les avertissements de danger de base. /5 | R22: 5 | S22: 1 | T22: 1 | U22: =S22*T22 -> 1 | V22: 0 | W22: =V22*U22 -> 0 | FA22: Demande de rapports réguliers sur les performances qualités des fournisseurs de rang 3 aux fournisseurs de rang 2 /10 | FB22: 8 | FC22: 5 | FD22: 5 | FE22: =FC22*FD22 -> 25 | FF22: 3 | FG22: =FF22*FE22 -> 75 | FV22: Adaptabilité des délais /10 | FW22: 2 | FX22: 0 | FY22: 0 | FZ22: =FX22*FY22 -> 0 | GA22: 0 | GB22: =GA22*FZ22 -> 0
Q23: Les managers sont entièrement responsables de leurs indicateurs en matière de sécurité. Ils les gèrent activement et dirigent les mesures d’amélioration pertinentes. Ils sont formés et capables de détecter la plupart des situations dangereuses et à risque. Au-delà de la simple réaction immédiate, ils sont en mesure de promouvoir des changements de comportement durables pour leurs collaborateurs. Chaque jour, ils consacrent beaucoup de temps aux questions de sécurité, comme les visites de sécurité, les réunions de sécurité, etc. /10 | R23: 10 | S23: 1 | T23: 1 | U23: =S23*T23 -> 1 | V23: 60 | W23: =V23*U23 -> 60
C25: 40 | J25: 55 | Q25: 60 | X25: 45 | AE25: 86 | AL25: 30 | AS25: 25 | AZ25: 25 | BG25: 25 | BN25: 50 | BU25: 25 | CB25: 10 | CI25: 10 | CP25: 10 | CW25: 10 | DD25: 10 | DK25: 60 | DR25: 40 | DY25: 30 | EF25: 20 | EG25: =SUM(EG13:EG18) -> 20 | EM25: 20 | EN25: =SUM(EN13:EN24) -> 3 | ET25: 30 | FA25: 75 | FH25: 80 | FO25: 20 | FV25: 100 | GC25: 15 | GJ25: 50
C26: Score sur 40 / Criticité % maturité / résilience (en Jours) | D26: =D13+D14+D15+D16+D17+D18+D19+D20 -> 40 | E26: =AVERAGE(E13:E20) -> 1 | F26: =AVERAGE(F13:F20) -> 1 | G26: =AVERAGE(G13:G18) -> 1 | H26: R(e) | I26: R(c) | J26: Score sur 55/ Criticité % maturité / résilience (en Jours) | K26: =SUM(K13:K25) -> 53 | L26: =AVERAGE(L13:L22) -> 1.2 | M26: =AVERAGE(M13:M22) -> 3.9 | N26: =AVERAGE(N13:N18) -> 4.1666667 | O26: R(e) | P26: R(c) | Q26: Score sur 60 / Criticité % maturité / résilience (en Jours) | R26: =SUM(R13:R25) -> 46 | S26: =AVERAGE(S13:S23) -> 2.0909091 | T26: =AVERAGE(T13:T23) -> 2.3636364 | U26: =AVERAGE(U13:U18) -> 7 | V26: R(e) | W26: R(c) | X26: Score sur 45 / Criticité % maturité / résilience (en Jours) | Y26: =SUM(Y13:Y25) -> 40 | Z26: =AVERAGE(Z13:Z20) -> 1.25 | AA26: =AVERAGE(AA13:AA20) -> 2.125 | AB26: =AVERAGE(AB13:AB18) -> 3.5 | AC26: R(e) | AD26: R(c) | AE26: Score sur 86 / Criticité % maturité / résilience (en Jours) | AF26: =SUM(AF13:AF25) -> 36 | AG26: =AVERAGE(AG13:AG20) -> 3.3333333 | AH26: =AVERAGE(AH13:AH20) -> 3 | AI26: =AVERAGE(AI13:AI18) -> 7.3333333 | AJ26: R(e) | AK26: R(c) | AL26: Score sur 30 / Criticité % maturité / résilience (en Jours) | AM26: =SUM(AM13:AM25) -> 30 | AN26: =AVERAGE(AN13:AN20) -> 1 | AO26: =AVERAGE(AO13:AO20) -> 0 | AP26: =AVERAGE(AP13:AP18) -> 0 | AQ26: R(e) | AR26: R(c) | AS26: Score sur 25 / Criticité % maturité / résilience (en Jours) | AT26: =SUM(AT13:AT25) -> 22 | AU26: =AVERAGE(AU13:AU20) -> 1 | AV26: =AVERAGE(AV13:AV20) -> 0.4 | AW26: =AVERAGE(AW13:AW18) -> 0.4 | AX26: R(e) | AY26: R(c) | AZ26: Score sur 25 / Criticité % maturité / résilience (en Jours) | BA26: =SUM(BA13:BA25) -> 15 | BB26: =AVERAGE(BB13:BB18) -> 1.5 | BC26: =AVERAGE(BC13:BC18) -> 0.75 | BD26: =AVERAGE(BD13:BD16) -> 1.75 | BE26: R(e) | BF26: R(c) | BG26: Score sur 25 / Criticité % maturité / résilience (en Jours) | BH26: =SUM(BH13:BH25) -> 17 | BI26: =AVERAGE(BI13:BI20) -> 4.25 | BJ26: =AVERAGE(BJ13:BJ20) -> 2.5 | BK26: =AVERAGE(BK13:BK20) -> 14.25 | BL26: R(e) | BM26: R(c) | BN26: Score sur 40 / Criticité % maturité / résilience (en Jours) | BO26: =SUM(BO13:BO25) -> 45 | BP26: =AVERAGE(BP13:BP20) -> 1 | BQ26: =AVERAGE(BQ13:BQ20) -> 1 | BR26: =AVERAGE(BR13:BR18) -> 1.1666667 | BS26: R(e) | BT26: R(c) | BU26: Score sur 25 / Criticité % maturité / résilience (en Jours) | BV26: =SUM(BV13:BV25) -> 22 | BW26: =AVERAGE(BW13:BW20) -> 1 | BX26: =AVERAGE(BX13:BX20) -> 2.2 | BY26: =AVERAGE(BY13:BY18) -> 2.2 | BZ26: R(e) | CA26: R(c) | CB26: Score sur 10 / Criticité % maturité / résilience (en Jours) | CC26: =SUM(CC13:CC25) -> 10 | CD26: =AVERAGE(CD13:CD20) -> 0.5 | CE26: =AVERAGE(CE13:CE20) -> 0.5 | CF26: =AVERAGE(CF13:CF18) -> 1 | CG26: R(e) | CH26: R(c) | CI26: Score sur 10 / Criticité % maturité / résilience (en Jours) | CJ26: =SUM(CJ13:CJ25) -> 5 | CK26: =AVERAGE(CK13:CK20) -> 0.25 | CL26: =AVERAGE(CL13:CL20) -> 1.25 | CM26: =AVERAGE(CM13:CM18) -> 1.25 | CN26: R(e) | CO26: R(c) | CP26: Score sur 10 / Criticité % maturité / résilience (en Jours) | CQ26: =SUM(CQ13:CQ25) -> 5 | CR26: =AVERAGE(CR13:CR20) -> 1.25 | CS26: =AVERAGE(CS13:CS20) -> 0.75 | CT26: =AVERAGE(CT13:CT18) -> 3.75 | CU26: R(e) | CV26: R(c) | CW26: Score sur 10 / Criticité % maturité / résilience (en Jours) | CX26: =SUM(CX13:CX25) -> 2 | CY26: =AVERAGE(CY13:CY20) -> 1.5 | CZ26: =AVERAGE(CZ13:CZ20) -> 0.75 | DA26: =AVERAGE(DA13:DA18) -> 4.5 | DB26: R(e) | DC26: R(c) | DD26: Score sur 10 / Criticité % maturité / résilience (en Jours) | DE26: =SUM(DE13:DE25) -> 10 | DF26: =AVERAGE(DF13:DF20) -> 0.2 | DG26: =AVERAGE(DG13:DG20) -> 0.4 | DH26: =AVERAGE(DH13:DH18) -> 0.4 | DI26: R(e) | DJ26: R(c) | DK26: Score sur 60 / Criticité % maturité / résilience (en Jours) | DL26: =SUM(DL13:DL25) -> 24 | DM26: =AVERAGE(DM13:DM20) -> 2.5 | DN26: =AVERAGE(DN13:DN20) -> 5.1666667 | DO26: =AVERAGE(DO13:DO18) -> 15.333333 | DP26: R(e) | DQ26: R(c) | DR26: Score sur 40 / Criticité % maturité / résilience (en Jours) | DS26: =SUM(DS13:DS25) -> 40 | DT26: =AVERAGE(DT13:DT20) -> 1.5 | DU26: =AVERAGE(DU13:DU20) -> 5 | DV26: =AVERAGE(DV13:DV18) -> 10 | DW26: R(e) | DX26: R(c) | DY26: Score sur 30 / Criticité % maturité / résilience (en Jours) | DZ26: =SUM(DZ13:DZ25) -> 22 | EA26: =AVERAGE(EA13:EA20) -> 1.75 | EB26: =AVERAGE(EB13:EB20) -> 1.5 | EC26: =AVERAGE(EC13:EC18) -> 2.75 | ED26: R(e) | EE26: R(c) | EF26: Score sur 20 / Criticité % maturité / résilience (en Jours) | EG26: =SUM(EG15:EG25) -> 20 | EH26: =AVERAGE(EH15:EH18) -> 0 | EI26: =AVERAGE(EI15:EI18) -> 0 | EJ26: =AVERAGE(EJ15:EJ17) -> 0 | EK26: R(e) | EL26: R(c) | EM26: Score sur 20 / Criticité % maturité / résilience (en Jours) | EN26: =SUM(EN13:EN24) -> 3 | EO26: =AVERAGE(EO13:EO20) -> 3.5 | EP26: =AVERAGE(EP13:EP20) -> 8.3333333 | EQ26: =AVERAGE(EQ13:EQ17) -> 30.4 | ER26: R(e) | ES26: R(c) | ET26: Score sur 30 / Criticité % maturité / résilience (en Jours) | EU26: =SUM(EU13:EU25) -> 5 | EV26: =AVERAGE(EV13:EV20) -> 5.25 | EW26: =AVERAGE(EW13:EW20) -> 7.5 | EX26: =AVERAGE(EX13:EX18) -> 45.25 | EY26: R(e) | EZ26: R(c) | FA26: Score sur 75 / Criticité % maturité / résilience (en Jours) | FB26: =SUM(FB13:FB25) -> 70 | FC26: =AVERAGE(FC13:FC19) -> 10 | FD26: =AVERAGE(FD13:FD19) -> 8.5714286 | FE26: =AVERAGE(FE13:FE18) -> 91.666667 | FF26: R(e) | FG26: R(c) | FH26: Score sur 40 / Criticité % maturité / résilience (en Jours) | FI26: =SUM(FI13:FI25) -> 52 | FJ26: =AVERAGE(FJ13:FJ20) -> 3.1428571 | FK26: =AVERAGE(FK13:FK20) -> 5 | FL26: =AVERAGE(FL13:FL18) -> 15 | FM26: R(e) | FN26: R(c) | FO26: Score sur 20 / Criticité % maturité / résilience (en Jours) | FP26: =SUM(FP13:FP25) -> 0 | FQ26: =AVERAGE(FQ13:FQ20) -> 2 | FR26: =AVERAGE(FR13:FR20) -> 2 | FS26: =AVERAGE(FS13:FS17) -> 20 | FT26: R(e) | FU26: R(c) | FV26: Score sur 100 / Criticité % maturité / résilience (en Jours) | FW26: =SUM(FW13:FW25) -> 2 | FX26: =AVERAGE(FX13:FX19) -> 2.8571429 | FY26: =AVERAGE(FY13:FY19) -> 1.4285714 | FZ26: =AVERAGE(FZ13:FZ19) -> 21.428571 | GA26: R(e) | GB26: R(c) | GC26: Score sur 15 / Criticité % maturité / résilience (en Jours) | GD26: =SUM(GD13:GD25) -> 14 | GE26: =AVERAGE(GE13:GE20) -> 3.6 | GF26: =AVERAGE(GF13:GF20) -> 8.2 | GG26: =AVERAGE(GG13:GG17) -> 32.4 | GH26: R(e) | GI26: R(c) | GJ26: Score sur 50 / Criticité % maturité / résilience (en Jours) | GK26: =SUM(GK13:GK25) -> 50 | GL26: =AVERAGE(GL13:GL20) -> 7.5 | GM26: =AVERAGE(GM13:GM20) -> 7.6666667 | GN26: =AVERAGE(GN13:GN18) -> 68.833333 | GO26: R(e) | GP26: R(c)
D27: =((D13+D14+D15+D16+D17+D18+D19+D20)/C25) -> 1 | E27: P | F27: I | G27: C | H27: =SUM(H13:H26) -> 0 | I27: =AVERAGE(I13:I25) -> 0 | K27: =K26/J25 -> 0.96363636 | L27: P | M27: I | N27: C | O27: =SUM(O13:O26) -> 13 | P27: =AVERAGE(P13:P25) -> 12.3 | R27: =R26/Q25 -> 0.76666667 | S27: P | T27: I | U27: C | V27: =SUM(V13:V26) -> 244 | W27: =AVERAGE(W13:W25) -> 180.45455 | Y27: =Y26/X25 -> 0.88888889 | Z27: P | AA27: I | AB27: C | AC27: =SUM(AC13:AC26) -> 10 | AD27: =AVERAGE(AD13:AD25) -> 1.25 | AF27: =AF26/AE25 -> 0.41860465 | AG27: P | AH27: I | AI27: C | AJ27: =SUM(AJ13:AJ26) -> 93 | AK27: =AVERAGE(AK13:AK25) -> 212 | AM27: =AM26/AL25 -> 1 | AN27: P | AO27: I | AP27: C | AQ27: =SUM(AQ13:AQ26) -> 0 | AR27: =AVERAGE(AR13:AR25) -> 0 | AT27: =AT26/AS25 -> 0.88 | AU27: P | AV27: I | AW27: C | AX27: =SUM(AX13:AX26) -> 10 | AY27: =AVERAGE(AY13:AY25) -> 4 | BA27: =BA26/AZ25 -> 0.6 | BB27: P | BC27: I | BD27: C | BE27: =SUM(BE13:BE26) -> 90 | BF27: =AVERAGE(BF13:BF25) -> 0 | BH27: =BH26/BG25 -> 0.68 | BI27: P | BJ27: I | BK27: C | BL27: =SUM(BL13:BL26) -> 140 | BM27: =AVERAGE(BM13:BM25) -> 585 | BO27: =BO26/BN25 -> 0.9 | BP27: P | BQ27: I | BR27: C | BS27: =SUM(BS13:BS26) -> 48 | BT27: =AVERAGE(BT13:BT25) -> 15.666667 | BV27: =BV26/BU25 -> 0.88 | BW27: P | BX27: I | BY27: C | BZ27: =SUM(BZ13:BZ26) -> 30 | CA27: =AVERAGE(CA13:CA25) -> 18 | CC27: =CC26/CB25 -> 1 | CD27: P | CE27: I | CF27: C | CG27: =SUM(CG13:CG26) -> 60 | CH27: =MAX(CH13:CH25) -> 240 | CJ27: =CJ26/CI25 -> 0.5 | CK27: P | CL27: I | CM27: C | CN27: =SUM(CN13:CN26) -> 180 | CO27: =AVERAGE(CO13:CO25) -> 225 | CQ27: =CQ26/CP25 -> 0.5 | CR27: P | CS27: I | CT27: C | CU27: =SUM(CU13:CU26) -> 360 | CV27: =AVERAGE(CV13:CV25) -> 1350 | CX27: =CX26/CW25 -> 0.2 | CY27: P | CZ27: I | DA27: C | DB27: =SUM(DB13:DB26) -> 180 | DC27: =AVERAGE(DC13:DC25) -> 810 | DE27: =DE26/DD25 -> 1 | DF27: P | DG27: I | DH27: C | DI27: =SUM(DI13:DI26) -> 0 | DJ27: =AVERAGE(DJ13:DJ25) -> 0 | DL27: =DL26/DK25 -> 0.4 | DM27: P | DN27: I | DO27: C | DP27: =SUM(DP13:DP26) -> 27 | DQ27: =AVERAGE(DQ13:DQ25) -> 141.5 | DS27: =DS26/DR25 -> 1 | DT27: P | DU27: I | DV27: C | DW27: =SUM(DW13:DW26) -> 0 | DX27: =AVERAGE(DX13:DX25) -> 0 | DZ27: =DZ26/DY25 -> 0.73333333 | EA27: P | EB27: I | EC27: C | ED27: =SUM(ED13:ED26) -> 75 | EE27: =AVERAGE(EE13:EE25) -> 60 | EG27: =EG26/EF25 -> 1 | EH27: P | EI27: I | EJ27: C | EK27: =SUM(EK15:EK26) -> 0 | EL27: =AVERAGE(EL13:EL25) -> 0 | EN27: =EN26/EM25 -> 0.15 | EO27: P | EP27: I | EQ27: C | ER27: =SUM(ER13:ER26) -> 300 | ES27: =AVERAGE(ES13:ES25) -> 1683.3333 | EU27: =EU26/ET25 -> 0.16666667 | EV27: P | EW27: I | EX27: C | EY27: =SUM(EY13:EY26) -> 101 | EZ27: =AVERAGE(EZ13:EZ25) -> 951.25 | FB27: =FB26/FA25 -> 0.93333333 | FC27: P | FD27: I | FE27: C | FF27: =SUM(FF13:FF26) -> 18 | FG27: =AVERAGE(FG13:FG25) -> 157.5 | FI27: =FI26/FH25 -> 0.65 | FJ27: P | FK27: I | FL27: C | FM27: =SUM(FM13:FM26) -> 20 | FN27: =AVERAGE(FN13:FN25) -> 58.571429 | FP27: =FP26/FO25 -> 0 | FQ27: P | FR27: I | FS27: C | FT27: =SUM(FT13:FT26) -> 50 | FU27: =AVERAGE(FU13:FU25) -> 1000 | FW27: =FW26/FV25 -> 0.02 | FX27: P | FY27: I | FZ27: C | GA27: =SUM(GA13:GA26) -> 60 | GB27: =AVERAGE(GB13:GB25) -> 600 | GD27: =GD26/GC25 -> 0.93333333 | GE27: P | GF27: I | GG27: C | GH27: =SUM(GH13:GH26) -> 0 | GI27: =AVERAGE(GI13:GI25) -> 0 | GK27: =GK26/GJ25 -> 1 | GL27: P | GM27: I | GN27: C | GO27: =SUM(GO13:GO26) -> 0 | GP27: =AVERAGE(GP13:GP25) -> 0
F30: % maturité | G30: Criticité | H30: R (client) en jours | J30: Nb de semaines ouvrées | K30: 48
C31: Propreté des lieux | F31: =D27 -> 1 | G31: =G26 -> 1 | H31: =I27/K31 -> 0 | J31: Nb de jours ouvrés dans la semaine | K31: 5
C32: Outillage / Qualité | F32: =K27 -> 0.96363636 | G32: =N26 -> 4.1666667 | H32: =P27/K31 -> 2.46
C33: Atelier | F33: =R27 -> 0.76666667 | G33: =U26 -> 7 | H33: =W27/K31 -> 36.090909
C34: Sûreté | F34: =Y27 -> 0.88888889 | G34: =AB26 -> 3.5 | H34: =AD27/K31 -> 0.25
C35: Conservation des données | F35: =AF27 -> 0.41860465 | G35: =AI26 -> 7.3333333 | H35: =AK27/K31 -> 42.4
C36: Maintenance | F36: =AM27 -> 1 | G36: =AP26 -> 0 | H36: =AR27/K31 -> 0
C37: Formation maintenance | F37: =AT27 -> 0.88 | G37: =AW26 -> 0.4 | H37: =AY27/K31 -> 0.8
C38: Disponibilité des pièces détachées pour mes fabrications | F38: =BA27 -> 0.6 | G38: =BD26 -> 1.75 | H38: =BF27/K31 -> 0
C39: Amélioration continue | F39: =BH27 -> 0.68 | G39: =BK26 -> 14.25 | H39: =BT27/K31 -> 3.1333333
C40: Formation des salariés | F40: =BO27 -> 0.9 | G40: =BR26 -> 1.1666667 | H40: =BT27/K31 -> 3.1333333
C41: Connaissance des employés | F41: =BV27 -> 0.88 | G41: =BK26 -> 14.25 | H41: =CA27/K31 -> 3.6
C42: Turn-over | F42: =CC27 -> 1 | G42: =CF26 -> 1 | H42: =CH27/K31 -> 48
C43: Accidentologie TG | F43: =CJ27 -> 0.5 | G43: =CM26 -> 1.25 | H43: =CO27/K31 -> 45
C44: Accidentologie TF1 | F44: =CQ27 -> 0.5 | G44: =CT26 -> 3.75 | H44: =CV27/K31 -> 270
C45: Accidentologie TF2 | F45: =CX27 -> 0.2 | G45: =DA26 -> 4.5 | H45: =DC27/K31 -> 162
C46: Dossier de recherche de cause accident | F46: =DE27 -> 1 | G46: =DH26 -> 0.4 | H46: =DJ27/K31 -> 0
C47: Aléas climatiques | F47: =DL27 -> 0.4 | G47: =DO26 -> 15.333333 | H47: =DQ27/K31 -> 28.3
...
